Workbook

Sheet Risks
A1: ID | B1: Workstream | C1: Assigned To | D1: Profile | E1: Priority | F1: Title | G1: Trigger_Date | H1: Countdown | I1: Days Open | J1: Update Log | K1: PMO Check | L1: URL
A2: 21 | B2: IAM | C2: Ted Balfour | D2: 4) Managing Sponsor | E2: 9 | F2: Application Remediation | G2: 26-Nov-12 | H2: 5 | I2: 231 | J2: 14-Nov: Per Ted on fortnightly RAID call, this is tracking to the trigger date. 100K synced so far, no issues. Another 50K users to be moved from tonight. 15 Oct: Approval for ID Sync deployment approved by CLT. JD&A effort still under way and deployment plan willbe adjusted to reflect anticapated remediation schedule. This item will remin open until the roll out is complete. 3-Oct: Per Ted, approx 11K apps analyzed, 19 require remediation, of those 8 are complete, 6 more with identified deployment dates. Ted presents to CLT today requesting approval to move forward with ID Sync and accept the risk that some apps may break. Ted will update thereafter. 22-Aug (LM): On fortnightly call, Ted took action to move trigger date, as this will not be impact until mid-Oct. 8-Aug (LM): Per Prog. RAID call, Ted said date will move out 2 months. Ted to add update and amend Trigger Date. 25-Jul (LM): Per Ted, doing assessment to see if can pushout date to service ready and go-live. Looking at what will happen if sync with O365 with data in current state. 20-Jul (SJ) Following 2 day Messaging / Lync workshop held 17/18th July the following updates were made during a deep dive on this point. - Approx 4/5000 apps still need to be assessed - Now within the scope of the J&DA program run by James Hartley. -IAM & M&C Program piloting standard attributes which will be required for Lync / Exchange / Outllok. - Process for Application Remendiation required - Funding of remediation required - Potential risk on SRT will occur - Action David Bingham to setup meeting with C. Driver, R. Bouji, N Sahdev, A. Harper, J. Els, N, Wood, and T. Balfour to discuss JD&A scope and Plan with James Hartley - Better control on Process / rules for coupling programs together (dependency process) - Ted to construct alternate plan 16-May: (LM) Ted on call: 20% of the 6,000 critical apps require remediation.Doing more detailed analysis now, following many avenues to resolve. 9-May: Resource availability is the risk here; 6,000 critical apps to analyze which is dependent on resource availability. 29-Mar: Added by Laura per Ted 29-Mar.​ | L2: http://sp.ey.net/msibm/Lists/Program%20Risks%20%20TEST/DispForm.aspx?ID=&RootFolder=*
A3: 22 | B3: IAM | C3: Ted Balfour | D3: 3) Program Mgt Team | E3: 6 | F3: AD Remediation - Complete the attribute cleansing | G3: 11-Oct-12 | H3: -41 | I3: 222 | J3: 5-Nov: All countries have now been sync'd with MMSSPP as far as im aware, but the error reports are currently going into no-mans land due to an addressing issue. Marina from IAM Ops is also driving MMSSPP error reporting processes etc. We have a meeting scheduled today on this topic. 9-May: Tolerance level 1% and we are just over that. Some remediation is taking place now. Still critical in terms of timeline. 28-Mar: Ted sent to Laura for addition to the log. LM emd Ted for details.​ | L3: http://sp.ey.net/msibm/Lists/Program%20Risks%20%20TEST/DispForm.aspx?ID=&RootFolder=*
A4: 23 | B4: IAM | C4: Ted Balfour | D4: 3) Program Mgt Team | E4: 6 | F4: ID SYNC - AD Attribute population & Standardazation. | G4: 26-Nov-12 | H4: 5 | I4: 201 | J4: 15 Oct: Data Standardazation kicking off 18 Oct and continuing for 6 weeks. Will review and close at the end of the deployment period. 9-May: Linked to R141 - until apps are remediated, can't do attribute population and standardization. 28-Mar: Ted sent to Laura for addition to the log. LM emd Ted for details.​ | L4: http://sp.ey.net/msibm/Lists/Program%20Risks%20%20TEST/DispForm.aspx?ID=&RootFolder=*
A5: 206 | B5: LNDR | C5: Christian Driver | D5: 3) Program Mgt Team | E5: 2 | F5: Onshore Notes developers are not secured for the duration of the plan. | G5: 30-Nov-12 | H5: 9 | I5: 71 | J5: CD, 19-Jul-12: Risk created (downgraded from issue).​ | L5: http://sp.ey.net/msibm/Lists/Program%20Risks%20%20TEST/DispForm.aspx?ID=&RootFolder=*
A6: 301 | B6: LNDR | C6: Christian Driver | D6: 3) Program Mgt Team | E6: 4 | F6: Later than planned deployment of EYAA may reduce number of deactivations in FY13 | G6: 07-Dec-12 | H6: 16 | I6: 28 | J6: CD, 18-Oct-12: Initial risk triggers not realised. Good progress on mitigating actions. Next review date moved back in line with next critical milestone/risk trigger. CD, 20-Sep-12: Risk created.​ | L6: http://sp.ey.net/msibm/Lists/Program%20Risks%20%20TEST/DispForm.aspx?ID=&RootFolder=*
A7: 74 | B7: Lync | C7: Stephen McCartney | D7: 3) Program Mgt Team | E7: 0 | F7: Inter-operability of Lync and existing softphones | G7: 30-Nov-12 | H7: 9 | I7: 207 | J7: 31-Oct-12: SM - Waiting for final recommendation from the technical team as to which headsets are recommended. 26/10 - Sandra to present options to DA w/e 09-Nov-12 ref options on how to handle the co-existence. 14-Sep: SM - Have pushed back the trigger and project review date as the technical analysis is now almost complete, and will be going to the DA for review on the 27th Sep. Following that meeting this will need to be updated with the outcome. 3-aug: BvG - Struggling a little to see this as interoperability issue beyond the technical issue of multiple audio applications using audio devices especially on the XP platform. Beyond that this is a change management issue that will require training. Existing softphone is no different from exisitng physical phone other than contention issues with audio devices etc. surely. 29-Jun: SM - Discussed in the Secaucus workshop. Agreed that this decision will need to go to the business - but first Sandra to provide a write-up of the inter-operability investigation. Tests have shown there are some issues with inter-operability, awaiting final results. | L7: http://sp.ey.net/msibm/Lists/Program%20Risks%20%20TEST/DispForm.aspx?ID=&RootFolder=*
A8: 76 | B8: Lync | C8: Neil Sahdev | D8: 3) Program Mgt Team | E8: 6 | F8: Parallel phases and programs may cause resource issues | G8: 30-Nov-12 | H8: 9 | I8: 204 | J8: 14-Sep: SM - Associated issue has been closed - reopening this as it will continue to be a risk throughout the project. Based on Sandra's update, I've updated this risk to push out the date of review until after Sandra's document has been seen by the DA. 11-Jul: SM - A recent call with John Murray has highlighted that he does not have enough time to complete work being assigned to him by Lync and O/E - he is going to have to prioritise one at the expense of the other. Both sets ​of work are on the critical path. | L8: http://sp.ey.net/msibm/Lists/Program%20Risks%20%20TEST/DispForm.aspx?ID=&RootFolder=*
A9: 78 | B9: Lync | C9: Stephen McCartney | D9: 3) Program Mgt Team | E9: 3 | F9: Offices' bandwidths may not support all Lync functionality | G9: 01-Jan-13 | H9: 41 | I9: 175 | J9: 09-Nov-12: SM - John Murray has the action to finish collecting the local office data. He is going to talk to Shaun Bradley to get more resource to get it completed. 26/10 - Call setup with John Murray Fri 02-Nov-11 to understand network analysis performed to-date, next steps, 'buy-in' required from network ops etc. 11-Jun: Deep dive will be done w/e 15-Jun to go futher into the infrastructure to try and make the bandwidth calculator more accurate. | L9: http://sp.ey.net/msibm/Lists/Program%20Risks%20%20TEST/DispForm.aspx?ID=&RootFolder=*
A10: 181 | B10: Lync | C10: Stephen McCartney | D10: 5) Steering Committee | E10: 4 | F10: Lync Performance Testing Approach Unresolved | G10: 31-Dec-12 | H10: 40 | I10: 123 | J10: 09-Nov-12: SM - Awaiting Sascha to update his strategy in line with the program managers requests. 26-Oct-12: SM - Sascha Mcdonald has been brought in as the M&C Performance Test Manager. He is currently working through a proposal for Lync Performance Testing which will be discussed and agreed on. | L10: http://sp.ey.net/msibm/Lists/Program%20Risks%20%20TEST/DispForm.aspx?ID=&RootFolder=*
A11: 32 | B11: M&C Program | C11: David Bingham | D11: 5) Steering Committee | E11: 9 | F11: Mechanisms for creating, storing and reusing components and other assets do not exist | G11: 01-May-13 | H11: 161 | I11: 154 | J11: 11-Sep: Per David, Trigger Date is May 2013; next monthly exec meeting to review after is 6-October 10-Sept (David): This is covered at the Exec meeting monthly. Therefore can I suggest we keep it at M&C level and based on the Exec meeting update it accordingly - it will remain a risk until Sharepoint 1 is live at least ! LM> David for trigger date, next review. 10-Sept (Brett): Not to do with Enterprise Plan; Certainly it impacts our ability to execute an enterprise plan of interdependent programs using/building SharePoint but they key issue is that while we need to be able to share SharePoint components etc between programs there is currently nothing in place to actually allow/facilitate this beyond individual developers and delivery programs more broadly talking to each other, establishing what is being worked on and available etc. The issue therefore results in a situation where business cases are being approved for independent programs to proceed (SDET, GAAIT etc) on the basis that they will share components etc and where our leadership believes this is actually achievable at scale. It is not and would be entirely ad hoc causing either high overhead to achieve or causing it simply not to happen. 4-Sept (LM): LM > Ian for guidance; convo may be needed amongst Chris, David and Brett to align. Per Brett, "This does not address the issue. The things Brian has linked to have always been there. The issue here is that in a practical way there is no real ability for programs to share code/components in the way that is expected by our leadership when they approve parallel efforts such as M&C with GAAIT Replacement, SDET, Oceania Records Management etc. We don't have the internal disciplines or processes and the reality is that code is not shared or managed and is, on the ground, reinvented etc." Ian agreed, 6-Sept, LM > Brett/David to gauge interest in such a call. 29-Aug (LM): E-mailed Brett with details to confirm whether resolution is satisfied by the processes described in the documentation linked below. 23-Aug (LM): Susan Pietretti discussed with Brian Blinco who confirmed that there is a process (documented) around reusable assets/components. He offered to discuss with someone from M&C if needed. Laura > David and Ian with this update; if satisfactory for the need specified in this risk, close. Links here: http://connections.ey.net/wikis/home?lang=en#/wiki/Strategy%20%26%20Architecture%20Library/page/Standards%20%26%20Roadmaps%20-%20Platform%20Usage%20and%20Enablement http://quickr.ey.net/LotusQuickr/saea/PageLibrary852576A20065DF81.nsf/h_Toc/9816CEAF5A1BDD19852576A200661FB3/?OpenDocument&ts=1319201730153#%7Btype=1&unid=94C3A972E50260FDC12576DC007C5176%7D http://quickr.ey.net/LotusQuickr/saea/PageLibrary852576A20065DF81.nsf/h_Toc/9816CEAF5A1BDD19852576A200661FB3/?OpenDocument&ts=1319201730153#%7Btype=0&unid=97E8331E4EF2649D852578B5006CC452%7D 22-Aug (LM): Followed-up with Chris; Susan Pietretti will be in touch to discuss. 13-Aug (LM): Discussed with Ian and David and David suggested this would be more appropriately owned by Chris d'Arcy as it is really a risk broader than just M&C. Laura emailed Chris for his input/agreement and update. 18-July: Per Alan, reassigned to David Bingham. LM > David to alert him of reassignment. 23-May: Rewrote Risk extensively following Wall discussion and follow-up between Nick Coburn, Andy Ioannou and Brett van Gelder 16-May: This needs to be escalated to Alan > IT Services leadership. Brett, Nick, and Andy MacRae to talk off-line and take to Alan by next week. 27-Apr: Team determined this is really a risk, not an issue. 23-Apr Brett: This is something that falls mostly in Brian Blinco's Application Architecture function with some involvement from EA Standards Office (Andy Macrae). There is almost certainly need for commitment by IT Services CLT and possible implications from a Methodologies perspective. ​ | L11: http://sp.ey.net/msibm/Lists/Program%20Risks%20%20TEST/DispForm.aspx?ID=&RootFolder=*
A12: 208 | B12: M&C Program | C12: Geoff Thompson | D12: 3) Program Mgt Team | E12: 0 | F12: Test schedule does not allow for effective Integration Testing between O/E & Lync | G12: 07-Nov-12 | H12: -14 | I12: 91 | J12: 17-Oct: Geoff - move this out till after 7/11 when we have a program wide test planning workshop which will look at this and other integration issues. 16 Oct (SB): updated re Test appriach - Simon Barkley 12 Sep CB: reassigned to Geoff ​09 Aug CB: under review by Brian Ford, revising review date to end Sept. | L12: http://sp.ey.net/msibm/Lists/Program%20Risks%20%20TEST/DispForm.aspx?ID=&RootFolder=*
A13: 211 | B13: M&C Program | C13: Rachel Phillips | D13: 3) Program Mgt Team | E13: 2 | F13: Lack of a consolidated deployment strategy for Lync & OE | G13: 13-Dec-12 | H13: 22 | I13: 121 | J13: 26/10/12: RP: awaiting confirmation of final Lync dates and will work to ensure as much alignment as possible for the deployment of both tools. 28/08 (IW) - Meeting scheduled for 30th Aug to discuss alignment further, continued discussion with Lync team on detailed deployment plan and approach which should be ready during the next week. 14/08 (IW) - Regular meetings scheduled to discuss alignment between the teams and get clarity around the possible options. Next meeting 15th Aug. 31/07/12 - Updated details and changed status to active.​ | L13: http://sp.ey.net/msibm/Lists/Program%20Risks%20%20TEST/DispForm.aspx?ID=&RootFolder=*
... A19: 288 | B19: M&C Program | C19: Anthony Firmin | D19: 3) Program Mgt Team | E19: 9 | F19: It is not known how programs which are targeting FY13 release to users will be prioritised in deployment windows or how I&O are required to prioritise deployments given limited resources | G19: 30-Nov-12 | H19: 9 | I19: 69 | J19: 14-Nov: reviewed on fortnightly RAID call; a number of actions underway to look at how deployment schedules line up and the challenge around user experience.A follow-up meeting has been scheduled for next week. Reassigned to Anthony who has taken on the Ent. Planning role for M&C 12-Oct (LM): Combined risk 284 (related) into this. May need to split out based on effect (operational readiness / deployment schedules). Laura sent to Susan 12-Oct for input. 25-Sep (SP): There is a need for guidance from I&O and the Enterprise Planning function as regards the prioritization of deployments across IT Services to determine whether our deployment schedules need to be revised. ​ Escalated to C. D’Arcy 19-Sep (LM): Discussed on fortnightly RAID call; team suggested this be owned by Susan (in line with risk 284) as aren't sure if this is better driven by the Enterprise Planning team. Steve to inform Susan 19-Sep, Laura 20-Sep. 08/09/12: RB logged risk. RB to seek guidance via S Pietretti in Enterprise Planning team, B Pardoe will also raise via J Pritchard. RB also flagged to S Bradley for discussion.​ History of Risk 284 (combined into this): 3-Oct: Susan and Rewa meeting today to develop approach to reviewing deployment schedules. Moving fwd; date should be set for end of Oct. 19-Sep (LM): Discussed on fortnightly RAID call- Rewa scheduled a meeting (Monday) to increase understanding of overall enterprise plan and how will manage business impact of all planned change.The team suggested this should be owned by Susan Pietretti; Steve to inform Susan 19-Sep, Laura 20-Sep. 4-Sept (LM): Per Blaine, the current action on this is that he is working with Gil Levit to address the change impacts of the changes to the operating model, as they are defined​. Gil has surfaced with the leaders of I&O to get their input. | L19: http://sp.ey.net/msibm/Lists/Program%20Risks%20%20TEST/DispForm.aspx?ID=&RootFolder=*
A20: 356 | B20: M&C Program | C20: Paul Thomas | D20: 3) Program Mgt Team | E20: 6 | F20: No nominated one point of contact for Active directory for the programme | G20: 25-Nov-12 | H20: 4 | I20: 0 | L20: http://sp.ey.net/msibm/Lists/Program%20Risks%20%20TEST/DispForm.aspx?ID=&RootFolder=*
A21: 19 | B21: Outlook/Exchange | C21: Rachel Phillips | D21: 3) Program Mgt Team | E21: 9 | F21: Delays in confirming deployment velocity | G21: 16-Nov-12 | H21: -5 | I21: 238 | J21: 21-Nov (DB): Reassign to Rachel (inc. Rachel for awareness) 14-Nov: On fortnightly RAID call, action assigned to Laura to check in with Shaun - Shaun had taken an acction to set-up a task force to look at impact assessment. Neil suggested may either need a second related risk raised for Lync (and possibly Collaboration) or as an alternative make this a program-wide risk and assign to Shaun. 15-Nov: LM > Shaun for his input. 9-Nov IM - continuing to work with Gil through to network teams 1-Nov IM - Meeting arranged 8/Nov with I&O Gil Levit for update on I&O readiness and on Network Assessment validation. Updated trigger and review dates. 29-Oct IM - Related risks 306, 307 and issue 187. Working with I&O on support side for velocity through Shaun/Gil. Working with Network Operations to confirm network constraints before being able to confirm a true velocity that I&O would be required to support. 17-Oct: Reassigned to Ian McGeachie per Rewa on fortnightly RAID call. 3-Oct (MK): <><><><><><><><><><>with all the latest meetings we have had with Gil and the wider I&O groups, we now have a good understanding of the issues that they see can/will impact the plan. We have one more meeting tonight (that I need to prepare for) that will conclude the schedule of meetings...after that we will get a consolidated view of issues from Gil...however - so far we are committed to meet the deployment plan milestone (baseline) on October 15 04-Sep (IW): Service design sessions continuing, briefing by deployment held, explaining deployment approach and drivers. Expect output from sessions over the next couple of weeks which will then be used to drive any updates to the deployment schedule. 28-Aug (IW): Successful meeting held with I&O leadership, strongly supported by Shaun Bradley. Acceptance of need for high velocity understood and details into I&O/ST service design sessions, furthermore design sessions will be kicked off with deployment plan walkthrough presentation. 14-Aug (IW): Action plan in place with Service transition and I&O, aim to host meeting w/c 20th Aug with I&O leadership to ensure common understanding acceptance of planning criteria and constraints driving the plan to date. Taking output into I&O/ST design sessions. Changing next review to 24th August. Furthermore presentation of findings and latest plan will be made available to I&O workshop w/c 27th August, changing trigger date to following week from workshop. 8-Aug (LM): From Prog RAID call, Martin took action to update this item. Will review next week the impact of delaying confirmation of velocity. 19 June 12: Updated impact and effect to match the latest info around delays from I&O. They no longer expect to be able to meet the mid-august confirmation and don't have a new target date yet. We're meeting with Shaun and Nick to discuss on Monday 23rd. Moving the next review date accordingly to end of next week. 07 June 12 : Socialization of draft plan continues under the assumption that I&O will be able to support the velocity in the draft. Changed the review date and required resolution date as discussed with Martin Kremmer. 16 May 12: Working to get the relevant people to review. Currently, it is expected that the review of I&O team will take place on 30 May 12 ​30 Apr 12: Discussed with Martin kremmer: To be reviewed with Sophie.Required resolution date - TBD | L21: http://sp.ey.net/msibm/Lists/Program%20Risks%20%20TEST/DispForm.aspx?ID=&RootFolder=*
A22: 27 | B22: Outlook/Exchange | C22: Rachel Phillips | D22: 3) Program Mgt Team | E22: 6 | F22: There is a risk that end user experience will be impacted if Exchange deploys prior to, or at the same time as, Lync | G22: 23-Nov-12 | H22: 2 | I22: 190 | J22: 26/10/12: extended due date to when we have confirmed Lync timescales. Proposed management through comms and stakeholder engagement and will finalise this once the Lync timescales are confirmed. 08/09/12: RB: Latest update from Lync team is: Pre-pilot Test - April; Pilot - May; Deployment - June. OE Pilot is March, Deployment is April. Change team will manage communications and learning but until there is further clarity on Lync service, further detailed planning to mitigate this risk may be limited. 15/08: RB: Meeting rescheduled from 15/08 to 29/08 due to unavailability of participants. Review date deferred. 31/07: Meeting planned for 19/07was rescheduled as a result of Messaging Workshop and holiday. Meeting to be held 02/08. Trigger date moved back to end September when Lync plan will be more concrete and when we have a clearer view as to I&Os ability to support deployment schedules across Lync and Outlook. 11/07: Two meetings already held with Lync, Transition and Business deployment team. Further updates required when M Kremmer and M Laci return from holiday. Meeting to be scheduled by RB for 19/07 13/06: Lync scope will not be confirmed until the end of June, after which it will be possible to determine what the timeline for deployment is. There are currently suggestions that deployment is being targeted for February 2013 which will be right up against the planned Outlook Pilot. Confirm with Neil and Martin K how deployment plan will factor this in, confirm with Service Transition if Ops can support it, and confirm with Business change that they can plan for managing impact of each outcome on users. 23/05: Review again once Lync vendor in place and there is clarity on Lync delivery timescales​ 19/04/12: RB: Risk created out of decision to close D223 | L22: http://sp.ey.net/msibm/Lists/Program%20Risks%20%20TEST/DispForm.aspx?ID=&RootFolder=*
A23: 34 | B23: Outlook/Exchange | C23: Rachel Phillips | D23: 3) Program Mgt Team | E23: 6 | F23: There is a risk that we cannot determine the total duration of Outlook migrations or the impact on the FY13 budget and effort required from program and I&O resource, nor ability to confirm that we can complete the migrations to O365 in the required 34 wks | G23: 16-Nov-12 | H23: -5 | I23: 274 | J23: 21-Nov (DB): Reassign to Rachel (Rachel inc for her awareness) 9-Nov IM - continuing to work with Gil through to networks 1-Nov-2012 IM - Ownership taken. Working with I&O to determine capacity to handle volume, and to re-validate Network Assessment on velocity. meeting scheduled 8/Nov, next update 9/Nov. Trigger and review dates updated. 08/09/12: RB: Deployment schedule to be validated with Stakeholders by M Kremmer. Contract with MSFT now has 3-month on-prem migration window built into commercial structure, Microland contract will also embed this. Changes to contractually agreed timeline will incur additional cost, program must bear the risk of this. Decision 256 requested to be made by Business Sponsors. J Brown confirmed this should be for the EY executive, not M&C EDG. As contracts now progressed, need to inform executive of risk of changes to migration schedule both for on-prem and O365 and request executive support in ensuring countries agree to migrate per schedule. Next review end of October per milestone for confirmed Business Deployment Schedule. 07/08: RB: Meeting held 02/08 to agree next steps. Nick Coburn to escalate via Service Transition on current I&O plans to manage deployment velocity, Martin to continue to validate migration schedule with business. Follow up meeting to be held 16/08. Network bandwidth assessment outcomes still pending. 20/07: RB: Wording of risk updated. Date moved back as further discussions need to be held with I&O and Business deployment to resolve. Date revised to end of August. 25/06/12: RB: Draft deployment schedule being circulated by Business Deployment team, ongoing discussions regarding what velocity operations can support. Meeting held 22/06 resulted in action for M Laci to secure from I&O an indication of maximum velocity they could support to feed into plan. M Kremmer to provide feedback from business re deployment plan/schedule. Follow up meeting scheduled for 29/06 30 May 12: Martin: Still awaiting confirmation from operations on their ability to support the velocity in the draft deployment plan 18-Apr: Can now start to work with operations to determine what migration velocity will be. Target to have deployment plan baslined at end of May. Updated due date from 20-Apr to 30-May. 02/04/12: RB: Draft pack developed by MK and RB with MK, needs to be presented for approval, already highlighted request for exception to black out periods. 09/03/12: RB: Meeting scheduled for 21/03/12 to agree migration strategy and velocity, and determine how these will be agreed with Microsoft, Ops, and Business 27/02/12: RB: Wording amended. Further discussion needed with Business Deployment, Transition Management, TF and MSFT to agree how to resolve these 22-Feb: Brett clarified: Msft does offer weekend migrations; the open question is that they have never had a client do only weekend migrations. EY had an assumption of weekend migrations in large part because we assumed we could do roll backs, which Msft has now told us with O365 they don't do rollbacks. EY needs to rethink assumptions on migration, thinking through the reasoning, Msft experience, etc. Rewa took an action to update the syntax of this item to reflect Brett's comments above. 21/02/12: RB: Added as output from Assumptions log. Assumption cannot be revalidated​ | L23: http://sp.ey.net/msibm/Lists/Program%20Risks%20%20TEST/DispForm.aspx?ID=&RootFolder=*
A24: 36 | B24: Outlook/Exchange | C24: Alexa Briggs | D24: 3) Program Mgt Team | E24: 3 | F24: Unconfirmed how 3-way lookup will work across O365, on-prem and LN. | G24: 28-Dec-12 | H24: 37 | I24: 230 | J24: 8-Oct - SOW in place, confidence will not be increased until we start testing in December (earliest) 17-Sept - hardware now available and SOW approaching agreement. Risk will be closed once SOW is signed and microsoft is on the hook to deliver a working solution into test 08/08 (PN) - Migration & coex signed off and agreed. Coex VMs ordered and implementation proceeding. Migration & Coex SOW WIP to put Migration on the hook for making 3 way work. Nxt review when have hardware, SOW etc. 22/06 (PN) - Migration & Coexistence document still to be signed off expected final review 28/06 07/06 (PN) - Migration & Coexistence document revisd and under review which will detail the design for the three way coexistence - need to resolve and prove the design before Service Ready for Exchange 13 Nov. 16/05 (RB): Migration & Coexistence document under review, aim is to complete in 3 review cycles rather than 5. With DA for review completion w/e 25/05 ​01/05: - Migration & Coexistence document expected 03_May, will include 3 way design from LN to Exch On_prem & Cloud 15/03/12: RB: CR026 with CCB for approval. Risk downgraded to minor but not to be closed until design is delivered. 12/03/12: RB: CR has been raised by TF Exchange to Microsoft to produce the design for 3-way coexistence. This has not been done before by Microsoft 27/02/12: RB: Update received from PN: "The change request to introduce the work to define the 3-way coexistence into the exchange On-Prem SOW, is still being drafted by Microsoft. We expect it to be delivered to us this week. We do know BinaryTree have a established POC of the threeway in their lab." 22-Feb: Paul and TF in conversations with Msft. Awaiting response from Msft. 21/02/12: RB: Added as output from Assumptions log. Assumption cannot be revalidated (Legacy A72) | L24: http://sp.ey.net/msibm/Lists/Program%20Risks%20%20TEST/DispForm.aspx?ID=&RootFolder=*
A25: 144 | B25: Outlook/Exchange | C25: Charles Sclater | D25: 3) Program Mgt Team | E25: 6 | F25: Dependency on JD&A for application readiness in preparation for rollout/deployment to Pilot countries | G25: 30-Nov-12 | H25: 9 | I25: 147 | J25: 19 Nov - CS working with Deployment to re-plan ZA and DE To Be ExMIA Application Landscape. ZA replanned to sign off 23 Nov,DE signed off 30 Dec. 05/11/12 - CS working with JD&A and SD to finalise/agree DE & ZA As Is and To Be AppLandscapes. scheduled for 16/11/12 12/10/12 - Lock down on pilot countries South Africa, Germany and Ireland. Working with pilot ocuntries to work out remediation. Charlie Sclater 1 Oct South Africa and Germany have been identified as the two Pilot countries for Cloud and On Perm respectively Charlie Sclater 25 Sep: Working with Deployment and JD&A to idetify and prioritise remediation activities. Developed high level stage plan to manage/deliver rememediation for Pilot. 19-Sep (LM): Per Rewa on fortnightly RAID call, working through this with JD&A team; have provided a high level plan and working with James H. to confirm can meet timelines. Trigger date moved out to close of next week. 5-Sept (LM): Rewa will raise for wall call tomorrow. 01-Aug: Steps being taken to resolve challenges surrounding D&A to ensure that impact assessment is completed and applications start getting remediated through the Service Delivery 'channels' to allow impact applications to be reconfigured, enhanced and tested before the migration of users. 25-Jul: ​Martin provided update on RAID call; plan in place which will bring to mid-Sept before will know impact on the on apps. Socialize mid-October. Martin will update further. | L25: http://sp.ey.net/msibm/Lists/Program%20Risks%20%20TEST/DispForm.aspx?ID=&RootFolder=*
A26: 213 | B26: Outlook/Exchange | C26: Rewa Bouji | D26: 3) Program Mgt Team | E26: 4 | F26: Commitment for O365 and On-premises services to be consistent gives rise to cost impact for upgrading on-premises infrastructure and undertaking further on-premises migrations when O365 moves to Exchange 2013. This is not budgeted for in FY13. | G26: 30-Nov-12 | H26: 9 | I26: 103 | J26: 04/11: RB: Microsoft have confirmed that Exchange 2013 is not an in-place upgrade and will require parallel infrastructure to be installed in all on-premises locations. No detail as yet around likely extent of infrastructure that can be re-used. Highlighted to Exec Sponsor Meeting on 06/11 as a watch item. RB working with BvG and DB to agree next steps. 12/10/12 - RB - Further clartiy required date pushed. 07/08: RB: Meeting held with Peter Li from Microsoft to explain scope of change and likely impact on infrastructure budget. Total value of investment required not yet known. Meeting to be held in two months to determine what financial planning needs to be undertaken. It is expected that at this point there will be further clarity on Microsoft's release dates for Exchange 13, for confirmation of the FY13 budget and also on the on-premises deployment timeline which may influence investment decisions. 24/07: RB: Risk logged. Meeting to be held 01/08/12 with Peter Li to understand scope of impact as a result of upgrade. EY team to then discuss next steps and develop resolution/mitigation plan.​ | L26: http://sp.ey.net/msibm/Lists/Program%20Risks%20%20TEST/DispForm.aspx?ID=&RootFolder=*
A27: 222 | B27: Outlook/Exchange | C27: Rewa Bouji | D27: 3) Program Mgt Team | E27: 6 | F27: Risk the build of On-Prem countries in scope of DCC will slip (china and austraila) | G27: 31-Oct-12 | H27: -21 | I27: 79 | J27: 16/10/12: RB: RB, A Briggs & D Bingham met with Gareth Thomas in the DCC program 15/10. DCC are working on responding to our request for confirmation of the DCC schedule per our requirements, and also on the cost of each on-prem site build so that we can raise a CR for the costs (logged under R258). The estimate Gareth gave was that they would have a response in the next 2-3 weeks, but we did not have any firm date for delivery. 8-Oct - no response from DCC issue escalated to Rewa being managed in weekly calls with DCC and escalations | L27: http://sp.ey.net/msibm/Lists/Program%20Risks%20%20TEST/DispForm.aspx?ID=&RootFolder=*
A28: 259 | B28: Outlook/Exchange | C28: David Bingham | D28: 3) Program Mgt Team | E28: 2 | F28: Outlook/Exchange Delivery will proceed without the 8 "TBC" countries being included in scope | G28: 07-Dec-12 | H28: 16 | I28: 90 | J28: 21-Nov (DB): meeting to arrange with Tim / Mo / Alan - to work through the options and the impact of the delay in decision making - likely to be first week in December 16/10/12 RB - Risk ownership reassigned to David Bingham from C Burnside. Ian McGeachie leading activity to confirm country status, working with Q&RM. D Bingham has also escalated​ to J Murphy. Target is for resolution by mid November so that on-prem hardware orders can be submitted by 1 December 03-Sep-12 CB: risk accepted and explained to Q&RM and EYGS Account Lead for EMEAI Richard Sheldon. 12-Sep-12 CB: reduced Prob from Med to Low and Impact from High to Med. Also set next review to end of the year as possible that decisions for these 8 countries will take to end of year so risk remains until that time. | L28: http://sp.ey.net/msibm/Lists/Program%20Risks%20%20TEST/DispForm.aspx?ID=&RootFolder=*
A29: 279 | B29: Outlook/Exchange | C29: Shaun Bradley | D29: 3) Program Mgt Team | E29: 0 | F29: MSP Vendor Business case could be eroded if further on prem countries cannot be supported offshore | G29: 16-Nov-12 | H29: -5 | I29: 45 | L29: http://sp.ey.net/msibm/Lists/Program%20Risks%20%20TEST/DispForm.aspx?ID=&RootFolder=*
A30: 286 | B30: Outlook/Exchange | C30: Charles Sclater | D30: 3) Program Mgt Team | E30: 6 | F30: Approval/Budget for all Cross Org Application Remediation | G30: 30-Nov-12 | H30: 9 | I30: 74 | J30: 19 Nov CS: ZA and DE To BE ExMIA Landscape Singoff delayed to 23 & 30 Nov respectively. Milestone will drive ExMIA Remediation scope, resource requirements and budgets 5 Nov CS: working with JD&A and ZA&DE to approve To Be App Landscape due 16 Nov, which will then drive ExMIA's App Remediation scope 12/10/12 - reviewed by CS at RAID call. Charlie Sclater 1 Oct: JD&A has some budget to remediate priority applications, currently working with Deployment to prioritise EMIA applications. Current plan is to have assessment completed by 15 Oct Jon Els Focus is align and prioritise app remediation to support Deployment Schedule, thus remedation of Pilot Country's apps will be highest priority | L30: http://sp.ey.net/msibm/Lists/Program%20Risks%20%20TEST/DispForm.aspx?ID=&RootFolder=*
A31: 287 | B31: Outlook/Exchange | C31: Rewa Bouji | D31: 3) Program Mgt Team | E31: 0 | F31: There is a risk that program delivery milestones will be impacted by resource availability constraints over the Christmas period | G31: 23-Nov-12 | H31: 2 | I31: 68 | J31: 04/11: RB: OE plans under review to determine if any slippage will be caused by resource absence. 15/10/12 - RB - No comms from Cross Org or I&O. Resource gaps need to be identified in workstream plans as orginal timelines need to be adhered to. RB to continue to escalte with Alan/David. 28/08/12 RB: Logged. RB raised with DB and IB. DB agreed to discuss with AG and SB as requires coordinated response across Cross Org, I&O and other IT teams.​ | L31: http://sp.ey.net/msibm/Lists/Program%20Risks%20%20TEST/DispForm.aspx?ID=&RootFolder=*
A32: 311 | B32: Outlook/Exchange | C32: David Bingham | D32: 3) Program Mgt Team | E32: 4 | F32: Risk hardware ordered for on prem countries prior to country buy-in and design being proved will be incorrect and further duplicate spend needed for implementation | G32: 01-Dec-12 | H32: 10 | I32: 32 | J32: 2-Nov: Per David, no orders will be placed until BOM is defined and agreed - and country is cleared to be on prem - move out to December 1 for check point ​ | L32: http://sp.ey.net/msibm/Lists/Program%20Risks%20%20TEST/DispForm.aspx?ID=&RootFolder=*
A33: 329 | B33: Outlook/Exchange | C33: David Bingham | D33: 3) Program Mgt Team | E33: 6 | F33: Countries not aware of the financial or operational impact of going On-Prem, so risk they won’t order required hardware on time | G33: 16-Nov-12 | H33: -5 | I33: 30 | J33: 21-Nov (DB): Meeting held with Paula Bowie - to build the cross charge framework - need to take the message and use the area relationship managers, Sherry Martin and Paula Bowie, to cascade the approach. Remains overdue. 21-Nov (DB): Assign to David. 9-Nov IM - On Prem deadline escalated to Mo/Tim. Continues to be in focus. 22-Oct - risk raised and managed by the ongoing work of Ian McGeachie.​ | L33: http://sp.ey.net/msibm/Lists/Program%20Risks%20%20TEST/DispForm.aspx?ID=&RootFolder=*
A34: 139 | B34: SharePoint | C34: Dave Fraser | D34: 3) Program Mgt Team | E34: 6 | F34: SP15 Key Delivery Dates | G34: 15-Feb-13 | H34: 86 | I34: 138 | J34: 15 Oct - DF - MS has annouced RTM for SP 2013 and Office 2013 so the Dec data has been mitigated. Our remaining risk is RTM for 2013 on O365. This is scheduled for 1 April 2013 and EY has been identified to be included in the first wave of customers to upgrade. There will be a pilot upgrade with another customer in February so that will be our next checkpoint on this risk. See the bullets below that were provided by O365: Key point are as follows: - There was not a commitment by Dave or Bob E&Y would be upgraded by 4/1/12 - There are NO confirmed / committed upgrade dates yet. - The first wave is TARGETED to start in the April / May timeframe - The duration of the wave and upgrading are unknown at this point - E&Y is included in the first wave - The first pilot upgrade is targeted for February - After the first pilot is complete, a schedule will be determined 19 July (AI): Have adjusted required date and review date to align with RTM announcement. 19-July (LM): Per Andy, keep status active to track mitigations as related to RTM and SR in O365. Andy will adjust due date to be closer to RTM date. 18-July: Dave said he considers this closed but left for EY agreement. LM > Brett, Andy and David to confirm closure. Brett confirmed as the risk has been acknowleged and team is activly mitigating. 10th July : See updates in Risk Triggers above for latest on the dates. Participation in the TAP program which has started will give the team insight into the product quality throughout the pre-release cycle. 3rd July : (NC)​ Dave to update to reflect the latest known dates. Please ensure you include the fundamental change in understanding of Beta 1/2 | L34: http://sp.ey.net/msibm/Lists/Program%20Risks%20%20TEST/DispForm.aspx?ID=&RootFolder=*
A35: 242 | B35: SharePoint | C35: Sherry Martin | D35: 3) Program Mgt Team | E35: 6 | F35: Risk that will not deliver extranet capability in SP in time per business need | G35: 30-Nov-12 | H35: 9 | I35: 85 | J35: 5-Nov (SM) This is definitely not in scope for R1. As prioritization efforts for R2 are not likely to be concluded until end of November or mid December, this item will be re-evaluated to determine if the risk still exists. It is planned that extranet would be included in R2 scope; however, there are no agreements on how data would be kept secure, how users would collaborate (inside or outside of extranet) - essentially, requirements have not been fully gathered. 20-Sept (NC) Expectation is the Release 2 planning and scope prioritisatio will have been defined by 15th October. If the prioritised scope requires the extranet however the extranet itself is not part of the R2 scope mitigation will need to be considered. 17-Sep: David provided desc update, prob. and impact info, trigger date. Trigger date will be scope for R2 sign-off. 18-Sep: Lauren>Nicola for date. Laura to update once receive response. 27-Aug (AI): without completing roadmap planning for future Collaboration releases - planned Oct 2012 - M&C cannot commit to introducing extranet capability by Dec 2013. 14-Aug: Added by Laura per call with David and Ian. Laura > David for additional details.​ | K35: 6-Nov: LM > Sherry - new trigger date? | L35: http://sp.ey.net/msibm/Lists/Program%20Risks%20%20TEST/DispForm.aspx?ID=&RootFolder=*
A36: 336 | B36: SharePoint | C36: Andy Ioannou | D36: 3) Program Mgt Team | E36: 6 | F36: Beta Pilot Deploment Schedule at Risk, concern regarding risks to "happy path" deployment schedule | G36: 25-Nov-12 | H36: 4 | I36: 25 | J36: 19-Nov(LS): Merged Risk 346 "Concern regarding risks to "happy path" deployment schedule" assigned to Cynthia into this risk. 16-Nov (AI): black-out period from 17/12 - 04/01 being upheld by O365 team. HAve therefore had to rethink deployment approach and plan. Decision taken to split deployment into 2 batches: Batch 1 (core functionality): plan to start deployment following CVS completion (27/11 - 28/11) and complete by Fri 14th Dec. Solution would then, technically, be live and available for user operation, although this is only expected from the New Year. Batch 2: (non-core functionality comprising profile sync of custom attributes and deployment of search crawl to update indexes): plan to execute 4/1 - 30/1. Impact on users operating Beta Pilot during Jan is inability to search for content or people using custom attributes. Risk deemed acceptable, however, decision to go live in this state will be governed by 'Go / No Go' process. 29-Oct (AI): ​Awaiting repsonse from Howard as per contingency plan. | L36: http://sp.ey.net/msibm/Lists/Program%20Risks%20%20TEST/DispForm.aspx?ID=&RootFolder=*
A37: 47 | B37: Transition | C37: Nick Coburn | D37: 3) Program Mgt Team | E37: 6 | F37: Complex deployment of Outlook and SharePoint | G37: 30-Nov-12 | H37: 9 | I37: 249 | J37: 04/04: Remain at high. Further information on impact following Service Design. 7-Mar: Nick provided additional detail for this item. R107 closed as it is accounted for in this item.​ 31/07 - Still open as a risk. We need to agree the deployment approach to determine what the impact will be. Sessions are planned with Martin Kremmer. 18/09 - Nick Coburn - Still open - deployment schedule is still to be determined though I/O are working closely with deployment on this. 19/10 - Remain open until deployment plan finalised. Likely to become an issue as overall cost will increase. | L37: http://sp.ey.net/msibm/Lists/Program%20Risks%20%20TEST/DispForm.aspx?ID=&RootFolder=*
A38: 109 | B38: Transition | C38: Nick Coburn | D38: 3) Program Mgt Team | E38: 6 | F38: Cross programme release management | G38: 30-Nov-12 | H38: 9 | I38: 145 | J38: Nick Coburn 31/07 Still an open risk - working through with program and I/O but overall deployment and release strategy both within MC and across all programs is not clear. NC 18/09 - Still open and decisions remain re GCL5, and deployment and of Lync and OE. | L38: http://sp.ey.net/msibm/Lists/Program%20Risks%20%20TEST/DispForm.aspx?ID=&RootFolder=*
A39: 142 | B39: Transition | C39: Nick Coburn | D39: 3) Program Mgt Team | E39: 6 | F39: The current I&O Change Management process does not support the planed rollout velocity for Lync and Outlook. | G39: 30-Nov-12 | H39: 9 | I39: 123 | J39: ​Nick Coburn 31/07 - Engaged with Business Deployment team to ensure that I/O input is included in the deployment approach and schedule. Nick Coburn 18/09 - Still open and being worked with delivery team, deployment and I/O. Neext meeting w/c 17/09. | L39: http://sp.ey.net/msibm/Lists/Program%20Risks%20%20TEST/DispForm.aspx?ID=&RootFolder=*
A40: 318 | B40: Transition | C40: Nick Coburn | D40: 3) Program Mgt Team | E40: 6 | F40: I/O may not sign off deployment plan without IT Services as early adopters | G40: 16-Nov-12 | H40: -5 | I40: 18 | L40: http://sp.ey.net/msibm/Lists/Program%20Risks%20%20TEST/DispForm.aspx?ID=&RootFolder=*

Sheet Issues
A1: ID | B1: Workstream | C1: Assigned to | D1: Profile | E1: Impact | F1: Title | G1: Required_Resolution | H1: Countdown | I1: Days Open | J1: Update Log | K1: PMO Check | L1: URL
A2: 18 | B2: IAM | C2: Ted Balfour | D2: 3) Program Mgt Team | E2: 3) High | F2: No policies or procedures have been provided by M&C for Group Management | G2: 11-Dec-12 | H2: 20 | I2: 206 | J2: 19-Nov: Ted sent note that req res date should be moved to 11-Dec-12. 14-Nov: Per update from Rewa and Ted on fortnightly call, they discussed off-line and need a new date; Rewa will follow-up with Charlie and Matt for a confirmed closure date. 17-Oct: Action taken on fortnightly call for Rewa and Ted to discuss off-line; currently need to determine new date. 3-Oct: Per Rewa, this is progressing; Sunil and Charlie are driving this, business manager for group management confirmed. Workshops scheduled for next couple of weeks. 19-Sept (LM): Per Rewa on fortnightly call, IAM still waiting on OE for policies and procedures. Workshop is being scheduled to gain an understanding of the gaps and who the business/IT owners are of the app; this is to be held within 2 weeks. 17-Sept (DW). We are deploying the infrastrucutre into EYUA from the 18 Oct. As we currnetly have no areement with respect to these Policies etc, the Service will not be available (although ALL Functional Capabilities will be available but not "Switched On"), until M&C advise/confirm. FYI, IAM had a draft available, and will be socialising hese with M&C by COP Tuesday 18th Sept. 14-Sept (Ted): I have passed this on to all parties involved to provide proper updates, including a resolution date by the next RAID meeting. 5-Sept (LM): Per Ted on fortnightly call, he will follow-up with Rewa and Nikolay. 29-Aug: LM > Daren again per Ted for date. 23-Aug: Charlie, Daren and Ted discussed and agree this should remain open. Laura > Daren, Ted for true RRD. 22-Aug (LM): Per fortnightly call, looking to roll out Group Management in October, but won't be effective without policies and procedures. Charlie was in a workshop with Ant Harper, Nick Wood and Daren Wicks to discuss, and believes this is resolved. Ted to circle back with Daren for his input. Charlie also to assess in terms of milestones and whether there are any issues around the delivery date. 15 Aug - Strategic discussions around EY Group Management are being led betwen the IAM DA, M&C EA and GLMS Team. Decisions are due w/e 17th Aug, that are very likely to impact what Group ID will deploy, and thus the associated Policies, procedures etc. A Draft version of this has now been provded by the GLMS Team, however, the review has been postponed until next week, when more direction wil be made available post this weeks Strategic conversations as mentioned above. This will also feed into the discussions and information required from M&C. Theses discussion will also impact the required by date. As mentioned in the description field above, IAM are NOT responsible for these policies, and thus we may end up in a situation where we deploy the Product and associated capabilities, and M&C will work with a viaraety of teams to Manage and deliver the associated Policies etc. Clearly we (IAM) are trying as much as possile to help, but we cannot delay the deployment into Production, as there are also competing Programs looking to utilise this service. DCC being but one example. 8 Aug - Provided feebdack to M&C Team. Awaiting feedback on next steps. 25-Jul (LM): Per Ted, Rewa's team working to provide this; updated date pending. Ted will update. 30-May (LM): Rewa - a BA is helping out on this and the output will go to governance group. This will remain open until there is a solid approach on groups. 9-May: Paul will follow-up with Rewa for an update and due date. 27-Apr: per Daren, R126 now an issue. 14-April - Requirements discussions are now taking place betwen M&C and IAM. This is now also an issue, and thus shoulod be moved to the issues log.​ | L2: http://sp.ey.net/msibm/Lists/RAID%20%20Issues%20TEST/DispForm.aspx?ID=&RootFolder=*
A3: 98 | B3: LNDR | C3: Christian Driver | D3: 3) Program Mgt Team | E3: 2) Medium | F3: No decom/archive capability within I&O | G3: 23-Nov-12 | H3: 2 | I3: 141 | J3: CD, 15-Nov-12: Update provided in Planned Resolution. Next review date updated to reflect anticipated resolution date. CD, 02-Nov-12: Update provided in Planned Resolution. Next review date updated to reflect anticipated resolution date. CD, 18-Oct-12: Update provided in Planned Resolution. Next review date updated to reflect anticipated resolution date. CD, 20-Sep-12: Work started to plan out deactivation capability with I&O. Plans updated to reflect this (CR100). Issue left open to ensure continued focus on finding a timely resolution. CD, 02-Aug-12: Updated issue to reflect conversations with I&O that indicate they will not able to support deactivation work until at least November 2012.​ | L3: http://sp.ey.net/msibm/Lists/RAID%20%20Issues%20TEST/DispForm.aspx?ID=&RootFolder=*
A4: 190 | B4: Lync | C4: Neil Sahdev | D4: 3) Program Mgt Team | E4: 3) High | F4: ATT Plan does not support FY13 'go-live' for Lync | G4: 31-Aug-12 | H4: -82 | I4: 137 | J4: 14-Nov: Per Neil on fortnightly RAID call, working with AT&T, expecting an update after 4pm today. Neil to update thereafter. 2-Nov: LM > Neil for Planned Resolution/Affected detail.​ 26-Oct: NS > Neil raised to supercede Issue 20. 09/11 - NS - Escalation call scheduled Fri 09/11/12 | L4: http://sp.ey.net/msibm/Lists/RAID%20%20Issues%20TEST/DispForm.aspx?ID=&RootFolder=*
A5: 26 | B5: M&C Program | C5: Steven Jelf | D5: 3) Program Mgt Team | E5: 3) High | F5: Limited traction being made on reducing the outstanding dependencies. | G5: 19-Dec-12 | H5: 28 | I5: 301 | J5: 2nd Nov - This is an ongoing issue. Alignment now reduced to 31%over the last month. Many mis-alignments due to PMs not speaking and agreeing dates / updating plans. Working with EP team on Interdependencies between programs, especially regarding better alignment processes between M&C and IAM programs. Additional work now being undertaken regarding internal dependency management within the Outlook / Exchange team. Date being pushed back by one month to monitor progress. This issue will be ongoing. 2nd Oct SJ) - Deep Dive session highlighted additional concerns so depdendency alignment was not the focus. Overall we continue to be aligned around 55%. Further deep dive session to be held, once plans are re-baselined for Exchange / Outlook, AT&T have a plan that EY buy into for Lync and it is understood how we can best align dependencies between to / from SharePoint given that the Infrastructure element of Collobaration is not longer aligns with EY Planning standards. The situation is being monitored, but pushing date out to end of Oct. 19-Sep (LM) - Per Steve on fortnightly call, traction being made, almost to 60% alignment. Areas of concern include lack of DCC schedule. Drains up review scheduled for 26-Sept. 4th Sept Traction being made on IAM dependencies - session held with Bharat (IAM dependency contact). Currently IAM use a separate spreadsheet to update depedencies, however there is no linkage to dependencies stored on IAM plans which is the central source for the EP team to take and produce metrics each week. Agered with Bharat that a separate follow up will occur weekly to ensure alignment is known and missing dependencies are entered on relevant plans. 20th Aug - Further internal dependencies coded regarding Outlook / Exchange. SP dependencies reviewed and work stream is standardising descriptions. PMO process documented and in place. Dependency aligment has risen above 50% for the first time in several months, Further work required to align dependencies internally to the work streams which will still take a number of weeks to code / correlate, but positive movement is being made. 1st Aug - Further internal dependencies have now been coded. Full analysis of dependency alignment report has occured. MEssaging fortnightly external program dependency meetings recommenced 1st Aug. Alignment now creeping up and will be over 40% this week. Further session organised with Enterprise Planning team on the internal dependency coding efforts required. 11th July - Date moving out - Planning standards enhancements being embedded into the plans and internal dependencies are now being fed into the plans allowing the complete picture to be tracked. This will be a gradual process. 13th June - Due to Program changes (ADM, SharePOint etc), Level 3 plans need again to be updated. Once this occurs, dependencies can then be removed / adjusted. Lync dependencies still not clear at this point, Majority of the Exchange / Outlook dependencies have been coded. - Further work required on alignment especially with the DCC Program. 09th May - EP team still coding of new dependencies. Starting to re-align dependencies and holding bi-weekly meetings with all teams. This will be a gradual process that will still take a number of weeks to resolve. 16th April Level 3 detailed plans starting to be reconstructed and dependencies at least on the core dependent programs (IAM) starting to be agreed. Dependencies between ADM and SharePoint now also starting to be aligned and dependency meetings now set up for all core programs. Further work is required on the revised org structure / remaining dependencies as previous dependencies now need to be validated. This will be a slow process to amend and fix, but the process has now started 4th April - Work continues on replanning. Level 0 and 1 plans are now in place for all work streams. However, detailed MPP's need to be rebaselined. Dependency management meetings will occur after Easter every 2 weeks. Working with EP team to code new dependencies when plans are re-baselined. 17th March - As expected, dependencies have reduced in alingment due to new plans being submitted. Resolution will be (a) Ensure Org restructure is known to determine if dependencies still exist. Secondly fortnightly meetings occuring on aligning dependencies throughout the M&C program 7th March - Dependencies are still likely to reduce over the next weeks whilst plans are now being refined based on potential org structure changes. 29th Feb - Dependency Alignment will dip further over the next 2 / 3 weeks as new plans replace the originals. Dependency alignment meeting with key external programs booked every 2 weeks from 15th March 15th Feb - Dependency alignment reduced to 51% - SharePoint and TF Lync plans are effectively shelved and a new plan is being constructed. Dependencies will be mis-aligned at least until 1st March, 31st Jan - Dependency alignment 58%. 2 plans will be dropped (Lync and SharePoint) as a complete replanning exercise is required. Therefore dependency alignment is projected to drop further. 23rd Jan - Dependency alignment 53%. There are a number of dependencies that could be aligned , but due to significant replaninng tasks being undertaken, current plans are effectively shelfed at this point. 17th Jan - Dependency alignment 49%. This will continue to drop as plans need validation. 11-Jan: Steve thinks got up to 60% this week, but this will probably reduce as replan on account of BPOS. As for a req. resolution date, this is dependent on re-planning of the SP and Exchange streams. For now, TBD; review again end of February. 06th - Jan. Dependency management meetings held with M&C Program Managers and external programs every 2 weeks, but in certain work streams sufficient priority isn't given to resolving this. ​ | L5: http://sp.ey.net/msibm/Lists/RAID%20%20Issues%20TEST/DispForm.aspx?ID=&RootFolder=*
A6: 116 | B6: M&C Program | C6: Laura Murphy | D6: 3) Program Mgt Team | E6: 3) High | F6: Exceeded item threshold limit for M&C Program library in SP | G6: 12-Dec-12 | H6: 21 | I6: 118 | J6: 13-Nov (LM): Continuing efforts to reduce documentation stored in site. Laura working with Scott around the possibility of increasing storage capacity. 2-Oct: Call with Ian and Brett. Workstream/library split to being with PMO mid-week, other workstreams to follow. Laura to submit newsletter article for this and next with what is coming and best practices moving forward. Upon moving will further restrict version history. Found Web Analytics and will use this to monitor Storage issue. Will encourage indiv to clean out documentation, reorg to use less folders, etc. Follow-up call scheduled 9-Nov to review progress. 14-Sep (LM): Flipped setting to save drafts for 10 major versions; no effect on item count. Meeting scheduled with Ian and Brett to discuss further on 28-Sept. Will then run a sanity check of plan by Norm or Mike N. Also thinking about this in terms of being able to provide guidance to future instances of SP. 12-Sep (LM): Discussing with Ian on 13-Sep; suggest implement setting of save draft versions for 10 mjr versions (likely will not have an impact) Thereafter sched meeting with Ian and Brett to discuss options for refining the setting. 5-Sept (LM): Plan to test setting on separate folder/library; see how works so can best determine # major versions to keep minor versions for. PMO continues to take re-org of SP site forward. 29-Aug (LM): Setting works differently than anticipated; working with Brett to determine # of versions (maintains minor versions for X number of major versions, as opposed to say, 10 minor versions). 14-Aug (LM): Second comm announcing the impending version limit settings (10 minor, unlimited major) distributed 13-Aug with implementation date of 28-August. Review at that point. 25-July (LM): Discussed on program RAID call; agreement by those on call to request clean-up actions be taken by streams to clean-up. First comm pending approval by David prior to send. 19-July: Added to RAID log by Laura. Action plan established and agreed with Ian/Steve. Initial comm to inspire awareness and behavior change drafted and sent to Steve/David for their review. Brett working with Msft team to determine areas where there are a large number of versions saved that will help us to determine 1. areas where we may lose versions upon implementing a limit, and 2. an appropriate limit to set such that we maintain a beneficial history of changes, but not so many that we cross the threshold.​ | L6: http://sp.ey.net/msibm/Lists/RAID%20%20Issues%20TEST/DispForm.aspx?ID=&RootFolder=*
