Workbook

Sheet Instructions
A1: Worksheet name | B1: How to use
A2: General | B2: 1. For each worksheet, enter the project name and last updated date in the header 2. Project leads and managers will raise items from their individual project RAIDs to the program level RAID if it cannot be resolved within the project and/or if it has an impact at the overall program level (scope, quality, cost and schedule). 3. The person identifying and raising the item to the log must follow the instructions outlined below to properly define the item. It is critical for this person to: a. Clearly describe the item, including its potential effect or impact on the program b. Assess each impact category (quality, scope, cost and schedule) with your workstream lead c, Talk to potential item owner or assigned party and agree ownership. If nobody is identified, assign to item identifier. 4. The person assigned to the item is responsible to: a. Manage until action plan completed. b. Create an action plan. c. Manage changes and tasks d. Keep workstream lead informed e. Update working notes, review notes and other fields as described below.
A3: Risks
A4: Risk Log | B4: 1. Enter a unique # for the Risk; this number serves as the item reference number. Proceed in numerical order such that first risk added to the log has # R1, the second R2, etc. 2. Enter the Date Captured. The Date Captured is the date on which the risk is discovered. 3. Enter the name of the person who raised the risk to the log in the Identified by column. 4. Select the Status from the dropdown list. The risk can be 01. Open, 02. Open & Assigned, 03. Action/Mitigation Plan Defined, 04. Action Plan Complete, 05. Risk Closed, 06. Deferred, 07. Risk has become an Issue, 08. Blank 5. Enter information in the Cause column. A Cause describes what may have created the risk and may be a requirement, assumption, constraint or condition that creates the possibility of negative or positive outcomes. 6. Enter description in the Risk column. A Risk is a threat (bad event) or an opportunity (good event) that may positively or negatively impact a project. Risks may be unknown factors. 7. Enter information in the Effect column. Describe to what the risk could/would/may lead. 8. Select the Workstream/Project/Program which owns the risk. It can be App and Data Migration, Change Management, IAM, M&C Program, SharePoint, Technology Foundation or Unified Communications. 9. Enter the name of the person who is the Risk Owner. The risk owner is someone from within the current program assigned to monitor the risk. 10. Enter the person Assigned to manage the risk. 11. Select the Priority from the dropdown list. It can be Critical, High, Moderate, Minor or Negligible. See chart in Ratings tab. 12. Select the Proximity. Proximity is, from a time perspective, how close the risk is to occurring Can be Impact < 4 weeks, Impact > 4 weeks, Impact > 3 months. 13. Select the Risk probability from the dropdown list. It is the likelihood that the risk will occur. It can be 01. Unsure, 02. Slight, 03. Doubtful, 04. Possible, 05. Probable, or 06. Certain. See the Probability chart in Ratings tab for further definition. 14. Select the impact factor this risk will have on the project Scope from the dropdown list. It is the effect on the project's scope if the risk occurs. See Impact table in Ratings tab for further clarification. 15. Select the impact factor this risk will have on the project Quality from the dropdown list. It is the effect on the project's quality if the risk occurs. See Impact table in Ratings tab for further clarification.
B5: 16. Select the impact factor this risk will have on the project Schedule from the dropdown list. It is the effect on the project's schedule if the risk occurs. See Impact table in Ratings tab for further clarification. 17. Select the impact factor this risk will have on the project Cost from the dropdown list. It is the effect on the project's cost if the risk occurs. See Impact table in Ratings tab for further clarification. 18. Enter the Trigger description for the identified risk. It is the risk symptoms or warning signs that a potential risk might happen 19. Select the Risk response. It describes how the project team is going to respond to the risk event. Choose a value from the dropdown list. It can be: Undecided, Acceptance, Avoidance , Mitigation. a. Risk Acceptance - A risk response planning technique that indicates that the project team has decided not to change the PMP to deal with a risk or is unable to identify any other suitable response strategy. b. Risk Avoidance - A risk response planning technique for a threat that creates changes to the project management plan that are meant to either eliminate the risk or to protect the project management objectives from its impact. c. Risk Mitigation - A risk response planning technique associated with threats that seeks to reduce the probability of occurrence or impact of a risk. 20. Enter description of the Contingency plan. It is the fallback plan should the risk occur. 21. Enter the description of the Mitigation plan. It is the plan to mitigate the risk. 22. Enter the date and updates, changes and actions taken/planned in the Update Log (Progress). Be sure to include justification for any alterations made to the Required Risk Resolution Date. 23. Enter the Next Review Date, the date of the next meeting during which the risk should be reviewed. 24. Choose the Escalation level from a dropdown list. It can be Project Manager, Program Manager, Program Director, Managing Sponsor, Executive Sponsor, or Other. 25. Enter the Risk resolution description. 26. Enter the Required Risk Resolution Date. This is the date by which actions need to be taken to be able to close the risk. Any changes to this field must be documented and justified in the Update Log (Progress) column. 27. Enter the Actual Risk Resolution Date. This is the date that the risk is closed. 28. If the risk becomes an Issue or Change Request, document the reference number of the new item in Output Reference.
A6: Issues
A7: Issue Definition | B7: 1. Enter a unique # for the issue; this number serves as the item reference number. Proceed in numerical order such that first issue added to the log has # I1, the second I2, etc. 2. Enter the date the issue was discovered in the Date captured field. 3. Enter the name of the person who identified the issue in the Identified by field. 4. Select the Status for the issue in the Issue definition section as Active or Closed. 5. Enter the Input Reference # from the Risk log. When a risk is realized / occurs, it becomes an issue and should be tracked in the Issues log. This field will help to maintain an audit trail of the lifecycle of a risk to an issue. 6. Enter a description of the issue in the Issue description field. Include brief definition of the issue, along with details of the impact to the project/program. 7. Select the impact factor this issue will have on the project Scope from the dropdown list. Can be Undecided, Low, Medium, High, Critical. See Impact table in Ratings tab for further clarification. 8. Select the impact factor this issue will have on the project Quality from the dropdown list. Can be Undecided, Low, Medium, High, Critical. See Impact table in Ratings tab for further clarification. 9. Select the impact factor this issue will have on the project Schedule from the dropdown list. Can be Undecided, Low, Medium, High, Critical. See Impact table in Ratings tab for further clarification. 10. Select the impact factor this issue will have on the project Cost from the dropdown list. Can be Undecided, Low, Medium, High, Critical. See Impact table in Ratings tab for further clarification. 11. Select the Priority from a dropdown list. It can be Critical, High, Moderate, Minor or Negligible. This value will reflect the highest impact value from the impact-related columns.Therefore, by definition, if any of the Impacts are rated High or Critical, the Priority must rated High or Critical, as well.
A8: Issue Assignment | B8: 1. Enter the name of the person who is the Issue Owner. The Issue Owner is a person within the current program assigned to monitor the Issue. 2. Enter the person the issue is Assigned to. This is the person assigned to manage the issue. 3. Select the Workstream/Project/Program which owns the issue. It can be App & Data Migration, Change Management, IAM, M&C Program, SharePoint, Technology Foundation or Unified Communications.
A9: Issue Resolution | B9: 1. Enter the planned resolution option for the issue in the Planned Resolution field. 2. Enter the Next review date. This is the date of the next meeting on which the item should be reviewed. 3. Provide the Required Resolution Date for complete resolution of the issue. This is the due date. 4. Enter the date and updates, changes and actions taken/planned in the Update Log. Be sure to include justification for any alterations made to the Required Resolution Date. 5. Select the Escalation level from a dropdown list. It can be Project Manager, Program Manager, Program Director, Managing Sponsor, Executive Sponsor, or Other. 6. Enter the Actual resolution details available for this issue. 7. Enter the Actual Resolution date for the issue. 8. If the output is a Change Request, please enter the Output Reference #.
A10: Assumptions
A11: Assumptions Log | B11: 1. Enter a unique # for the assumption; this number serves as the item reference number. Proceed in numerical order such that first assumption added to the log has # A1, the second A2, etc. 2. Enter the name of the person who raised the Assumption to the log in the Identified by column. 3. Select the Workstream/Project/Program which owns the assumption. It can be App & Data Migration, Change Management, M&C Program, SharePoint, Technology Foundation or Unified Communications. 4. Enter an Assumption, with a brief description. 5. Enter the Potential impact if assumption proves to be false. 6. Enter the Forum/Individual that will be responsible for validating the assumption. 7. Enter details of the person who validated the assumption in the Validated by column. 8. Enter the date the assumption was last reviewed on in the Last review date column. 9. Enter the date for the next review of the assumption in the Next review date column. 10. Enter the date by which the Assumption must be validated in the Due Date column. 11. Select the Status of the item. It can be Validated, Not yet validated, Output to Risk/Issue or Obsolete. 12. Enter the Risk or Issue # as the Output Reference # if the Assumption has become one of these. 13. Enter any Comments you may have on the assumption.
A12: Decisions
A13: Decisions Log | B13: 1. Enter a unique # for the decision; this number serves as the item reference number. Proceed in numerical order such that first decision added to the log has # D1, the second D2, etc. 2. Enter the name of the person who raised the Assumption to the log in the Identified by column. 3. Select the Workstream/Project/Program which owns the assumption. It can be App & Data Migration, Change Management, M&C Program, SharePoint, Technology Foundation or Unified Communications. 4. Select the Status of the Decision. It can be Pending, Closed, Obsolete. 5. Enter the Target Date for the decision; that is, the date by which the decision must be made. 6. Enter the Decision date when this decision was made. When this date is entered, the Status of the item should be changed from Pending to Closed. 7. Enter the details of all Decision makers involved in making the decision. 8. Enter Decision Description and Impact of the decision. 9. Enter any Comments you may have about the Decision.

Sheet Ratings
A1: Impact: Risks and Issues
A2: Area | B2: 00. Undecided | C2: 01. Low | D2: 02. Medium | E2: 03. High | F2: 04. Critical
A3: Time | B3: Priority to be determine | C3: Impact on Critical Path is less than 5% | D3: Impact on Critical Path is between 5% and 25% | E3: Impact on Critical path is between 25% and 50% | F3: Impact on Critical Path is greater than 50%
A4: Cost | B4: Priority to be determine | C4: Impact on cost baseline is less than 5% | D4: Impact on cost baseline is between 5% and 25% | E4: Impact on cost baseline is between 25% and 50% | F4: Impact on cost baseline is greater than 50%
A5: Scope | B5: Priority to be determine | C5: Scope change which impacts Time or Cost greater than 5% | D5: Scope change which impacts Time or Cost between 5% and 25% | E5: Scope change which impacts Time or Cost between 25% and 50% | F5: Scope change which impacts Time or Cost between more than 50%
A6: Quality | B6: Priority to be determine | C6: Minimal quality deliverable issues | D6: Small amount of quality deliverable issues which require remediation | E6: Large amount of quality deliverable issues which require remediation at program level | F6: Large amount of quality deliverable issues which impact Time and Cost and which require remediation at senior level
A9: Risk Priority Definitions:
A10: Critical | B10: If the risk event occurs, the program/project will fail. Minimum acceptable requirements will not be met.
A11: High | B11: If the risk event occurs, the program/project will encounter major cost/schedule increases. Minimum acceptable requirements will be met. Secondary requirements may not be met.
A12: Moderate | B12: If the risk event occurs, the program/project will encounter moderate cost/schedule increases. Minimum acceptable requirements will be met; some secondary requirements may not be met.
A13: Minor | B13: If the risk event occurs, the program/project will encounter small cost/schedule increases. Minimum acceptable requirements will be met. Most secondary requirements will be met.
A14: Negligible | B14: If the risk event occurs, it will have no effect on the program/project. All requirements will be met.
A17: Issue Priority Definitions:
A18: Critical | B18: The issue will cause the program/project to fail. Minimum acceptable requirements will not be met.
A19: High | B19: The issue will cause the program/project to encounter major cost/schedule increases. Minimum acceptable requirements will be met. Secondary requirements may not be met.
A20: Moderate | B20: The issue will cause the program/project to encounter moderate cost/schedule increases. Minimum acceptable requirements will be met; some secondary requirements may not be met.
A21: Minor | B21: The issue will cause the program/project to encounter small cost/schedule increases. Minimum acceptable requirements will be met. Most secondary requirements will be met.
A22: Negligible | B22: The issue will have no effect on the program/project. All requirements will be met.
A25: Probability
A26: 05. Certain | B26: 91-100%: very likely the risk will occur
A27: 04. Probable | B27: 61-90%: likely the risk will occur
A28: 03. Possible | B28: 41-60%: even likelihood the risk will occur
A29: 02. Doubtful | B29: 11-40%: unlikely the risk will occur
A30: 01. Slight | B30: 0-10%: very unlikely the risk will occur
A31: 00. Unsure | B31: Investigation required
A33: Proximity
A34: 01. Impact less than 4 weeks
A35: 02. Impact greater than 4 weeks
A36: 03. Impact greater than 3 months

Sheet Risk Log
A1: # | B1: Date Captured | C1: Identified by | D1: Status | E1: Cause As a result of (cause) | F1: Risk (uncertain event) may occur | G1: Effect which could/would/may lead to (effect / impact) | H1: Program / Workstream | I1: Project / Workstream | J1: Risk Owner | K1: Assigned to | L1: Priority | M1: Proximity | N1: Risk probability | O1: Impact: Scope | P1: Impact: Quality | Q1: Impact: Schedule | R1: Impact: Cost | S1: Risk Trigger | T1: Risk response | U1: Contingency Plan | V1: Mitigation plan | W1: Update Log (Progress) | X1: Next Review Date | Y1: Escalation level | Z1: Risk resolution | AA1: Required Risk Resolution Date | AB1: Actual Risk Resolution Date | AC1: Input/Output Refernce | AE1: =TODAY() -> 40990 | AF1: Status | AG1: Today > Res. Date | AH1: 30-90 days | AI1: 91-180 days | AJ1: 180+ days | AK1: Critical or High | AL1: Days until Due | AM1: Due in the next week | AN1: Critical, High or Moderate
A2: R102A | B2: 40947 | C2: Neil Sahdev | D2: 07. Risk has become an Issue | E2: Delays confirming future state of each application - in-turn this will delay the A&DM Program Archiving, Decommmisioning and Replatforming applications. | F2: IT Service Delivery Leads are flagging that their teams do not have both the bandwidth and a charge code to review / validate the Rediscovery reports | G2: No response received from IT Service Delivery leads | H2: App and Data Migration | J2: Neil Sahdev | K2: TBC | L2: Critical | M2: 01. Impact < 4 weeks | N2: 04. Probable | O2: 01. Low | P2: 01. Low | Q2: 04. Critical | R2: 03. High | S2: No responses received from IT Service Delivery Leads | T2: Mitigation | U2: None - the decision on the future state of each application needs to be confirmed by the IT Service Delivery Leads on behalf of the business | V2: Host briefing sessions to provide support to the IT Service Delivery teams - in progress | W2: 07-Mar: Risk now closed as item has been raised as an issue (#140) 22-Feb: inc. in man. Pack again; waiting on Operating Model decision. 15-Feb: include in management pack. 8-Feb: Risk raised; Neil reqd this item go into the mng pack. Will impact when the team can do the work and thus has financial implications, as well. | X2: 40968 | Y2: Program Director | AA2: 40970 | AF2: =IFERROR(OR(Table4[[#This Row],[Status]]="02. Open & Assigned",Table4[[#This Row],[Status]]="01. Open",Table4[[#This Row],[Status]]="03. Action/Mitigation Plan Defined",Table4[[#This Row],[Status]]="04. Action Plan Completed",Table4[[#This Row],[Status]]="08. Blank"),"") -> FALSE | AG2: =IF(Table4[[#This Row],[Required Risk Resolution Date]]="","FALSE",IF($AE$1>Table4[[#This Row],[Required Risk Resolution Date]],TRUE,FALSE)) -> TRUE
A3: R106A | B3: 40967 | C3: Neil Sahdev | D3: 02. Open & Assigned | E3: If RFP lead time > 4 months | F3: Based on the time is has taken to finalise other M&C RFPs the lead time to procure vendor(s) required for the A&DM Portfolio Teams may not be sufficient for work commence 1st Jul'12. If this was the case then the delivery date of the target application would be impacted. | G3: The deployment of the first application replatforms from the portfolio teams would be delayed | H3: App and Data Migration | J3: Neil Sahdev | K3: Neil Sahdev | L3: High | M3: 02. Impact > 4 Weeks < 3 Months | N3: 04. Probable | O3: 01. Low | P3: 01. Low | Q3: 03. High | R3: 03. High | S3: If RFP lead time > 4 months | T3: Mitigation | U3: Defer start-dates of the Portfolio teams however this will defer the business benefits (i.e. decommissioning legacy apps) | V3: Gain agreement to the A&DM Operating Model (Issue 141) then work with Procurement to initiate the RFP process | W3: 16-Mar: Neil said there are a few actions remaining before closure (from his call with Alan). 06 Mar: The preferred approach to mitigating the risk is initiate the RFP process now however this is dependant on agreeing both the Operating Model and Resourcing Strategy for A&DM (issue 141) | X3: 40991 | Y3: Program Director | AA3: 40998 | AF3: =IFERROR(OR(Table4[[#This Row],[Status]]="02. Open & Assigned",Table4[[#This Row],[Status]]="01. Open",Table4[[#This Row],[Status]]="03. Action/Mitigation Plan Defined",Table4[[#This Row],[Status]]="04. Action Plan Completed",Table4[[#This Row],[Status]]="08. Blank"),"") -> TRUE | AG3: =IF(Table4[[#This Row],[Required Risk Resolution Date]]="","FALSE",IF($AE$1>Table4[[#This Row],[Required Risk Resolution Date]],TRUE,FALSE)) -> FALSE | AH3: =IF(AE3<30,FALSE,IF(AE3>90,FALSE,TRUE)) -> FALSE | AI3: =IF(AE3<91,FALSE,IF(AE3>180,FALSE,TRUE)) -> FALSE | AJ3: =IF(AE3>180,TRUE,FALSE) -> FALSE | AK3: =OR(Table4[[#This Row],[Priority]]="Critical",Table4[[#This Row],[Priority]]="High") -> TRUE | AL3: =Table4[[#This Row],[Required Risk Resolution Date]]-$AE$1 -> 8 | AM3: =IF(AL3<1,FALSE,IF(AL3>7,FALSE,TRUE)) -> FALSE | AN3: =OR(Table4[[#This Row],[Priority]]="Critical",Table4[[#This Row],[Priority]]="High",Table4[[#This Row],[Priority]]="Moderate") -> TRUE
A4: R23 | B4: 40674 | D4: 05. Risk Closed | F4: Relative scope of Application Migration (AM) and Solution Portfolio Asset Rationalisation (SPAR) unclear | H4: App and Data Migration | J4: Neil Sahdev | N4: 03. Possible | O4: 02. Medium | W4: 30/08- SPAR program now disbanded. Close. | X4: 40772 | Z4: Discussing emerging scope with SPAR program team. Updating AM charter accordingly. Will seek approval of same from SPAR. | AB4: 40785 | AE4: =$AE$1-Table4[[#This Row],[Date Captured]] -> 316 | AF4: =IFERROR(OR(Table4[[#This Row],[Status]]="02. Open & Assigned",Table4[[#This Row],[Status]]="01. Open",Table4[[#This Row],[Status]]="03. Action/Mitigation Plan Defined",Table4[[#This Row],[Status]]="04. Action Plan Completed",Table4[[#This Row],[Status]]="08. Blank"),"") -> FALSE | AG4: =IF(Table4[[#This Row],[Required Risk Resolution Date]]="","FALSE",IF($AE$1>Table4[[#This Row],[Required Risk Resolution Date]],TRUE,FALSE)) -> FALSE | AH4: =IF(AE4<30,FALSE,IF(AE4>90,FALSE,TRUE)) -> FALSE | AI4: =IF(AE4<91,FALSE,IF(AE4>180,FALSE,TRUE)) -> FALSE | AJ4: =IF(AE4>180,TRUE,FALSE) -> TRUE | AK4: =OR(Table4[[#This Row],[Priority]]="Critical",Table4[[#This Row],[Priority]]="High") -> FALSE | AL4: =Table4[[#This Row],[Required Risk Resolution Date]]-$AE$1 -> -40990 | AM4: =IF(AL4<1,FALSE,IF(AL4>7,FALSE,TRUE)) -> FALSE | AN4: =OR(Table4[[#This Row],[Priority]]="Critical",Table4[[#This Row],[Priority]]="High",Table4[[#This Row],[Priority]]="Moderate") -> FALSE
A5: R24 | B5: 40674 | D5: 05. Risk Closed | F5: Process of identifying "as is" applications, business and technical classification, and decision making not well defined. | H5: App and Data Migration | J5: Neil Sahdev | N5: 03. Possible | O5: 02. Medium | W5: 12/10 - Manually reaching out to the business on these applications. | X5: 40821 | Z5: Define processes as part of AM program. Seek approval from SPAR, DCC, and other programs with common interest. | AB5: ? | AE5: =$AE$1-Table4[[#This Row],[Date Captured]] -> 316 | AF5: =IFERROR(OR(Table4[[#This Row],[Status]]="02. Open & Assigned",Table4[[#This Row],[Status]]="01. Open",Table4[[#This Row],[Status]]="03. Action/Mitigation Plan Defined",Table4[[#This Row],[Status]]="04. Action Plan Completed",Table4[[#This Row],[Status]]="08. Blank"),"") -> FALSE | AG5: =IF(Table4[[#This Row],[Required Risk Resolution Date]]="","FALSE",IF($AE$1>Table4[[#This Row],[Required Risk Resolution Date]],TRUE,FALSE)) -> FALSE | AH5: =IF(AE5<30,FALSE,IF(AE5>90,FALSE,TRUE)) -> FALSE | AI5: =IF(AE5<91,FALSE,IF(AE5>180,FALSE,TRUE)) -> FALSE | AJ5: =IF(AE5>180,TRUE,FALSE) -> TRUE | AK5: =OR(Table4[[#This Row],[Priority]]="Critical",Table4[[#This Row],[Priority]]="High") -> FALSE | AL5: =Table4[[#This Row],[Required Risk Resolution Date]]-$AE$1 -> -40990 | AM5: =IF(AL5<1,FALSE,IF(AL5>7,FALSE,TRUE)) -> FALSE | AN5: =OR(Table4[[#This Row],[Priority]]="Critical",Table4[[#This Row],[Priority]]="High",Table4[[#This Row],[Priority]]="Moderate") -> FALSE
A6: R25 | B6: 40674 | C6: unknown | D6: 07. Risk has become an Issue | E6: timeline provided by Msft | F6: Timeline for conversion of 15 applications by Microsoft shows 20+ week schedule which if extrapolated for remainder of the applications would indicate Program would not complete by mid-2013. | G6: wouldn't complete by mid-2013, would still have aplpications running when the licensing expires | H6: App and Data Migration | J6: Neil Sahdev | K6: Neil Sahdev | L6: Moderate | M6: 01. Impact < 4 weeks | N6: 05. Certain | O6: 01. Low | P6: 01. Low | Q6: 04. Critical | R6: 03. High | W6: 10-Jan: Neil confirmed that this is really an issue. Made I91. 12/10 - 'Top Down' Program plan based on current known data; Neil and Martin to rebaseline plan in Q1'12 once data has been enriched through the Rediscovery project | X6: 40933 | Y6: Program Director | Z6: Became issue 10-Jan-2012 | AA6: 40939 | AB6: 10-Jan-2012 (became an issue) | AC6: I91 | AE6: =$AE$1-Table4[[#This Row],[Date Captured]] -> 316 | AF6: =IFERROR(OR(Table4[[#This Row],[Status]]="02. Open & Assigned",Table4[[#This Row],[Status]]="01. Open",Table4[[#This Row],[Status]]="03. Action/Mitigation Plan Defined",Table4[[#This Row],[Status]]="04. Action Plan Completed",Table4[[#This Row],[Status]]="08. Blank"),"") -> FALSE | AG6: =IF(Table4[[#This Row],[Required Risk Resolution Date]]="","FALSE",IF($AE$1>Table4[[#This Row],[Required Risk Resolution Date]],TRUE,FALSE)) -> TRUE | AH6: =IF(AE6<30,FALSE,IF(AE6>90,FALSE,TRUE)) -> FALSE | AI6: =IF(AE6<91,FALSE,IF(AE6>180,FALSE,TRUE)) -> FALSE | AJ6: =IF(AE6>180,TRUE,FALSE) -> TRUE | AK6: =OR(Table4[[#This Row],[Priority]]="Critical",Table4[[#This Row],[Priority]]="High") -> FALSE | AL6: =Table4[[#This Row],[Required Risk Resolution Date]]-$AE$1 -> -51 | AM6: =IF(AL6<1,FALSE,IF(AL6>7,FALSE,TRUE)) -> FALSE | AN6: =OR(Table4[[#This Row],[Priority]]="Critical",Table4[[#This Row],[Priority]]="High",Table4[[#This Row],[Priority]]="Moderate") -> TRUE
A7: R26 | B7: 40674 | C7: unknown | D7: 05. Risk Closed | E7: Lack of business SME availability | F7: Phase 1 plan completion data is dependant on availability of business users and IT service delivery resources to support required activities, i.e. acceptance testing, requirements workshops, etc. | G7: If can't meet the date, will delay completion of Phase 1. | H7: App and Data Migration | J7: Neil Sahdev | K7: Nicola Cooper | L7: Critical | M7: 01. Impact < 4 weeks | N7: 04. Probable | O7: 01. Low | P7: 01. Low | Q7: 03. High | R7: 03. High | S7: If the business and/or IT service delivery resources cannot confirm that they can support required activities, then will occur. | T7: Mitigation | U7: None - Business and IT Service Delivery resources are needed for Phase 1 | V7: Send to the business and IT services resources a list of activities they are expected to support to gain their commitment - in progress | W7: 06-Mar: Risk closed as scope of Phase 1 has been restructured to take into account the availability of the business SMEs 29/Feb :action pending planning meeting shed for Monday 5th March. 22/Feb: inc. in man. pack; still waiting to hear back on Operating Model. 15-Feb: Neil reqd we include in man. pack again. 08-Feb: Neil reqd we include this in the management pack. 07-Feb: The A&DM Operating Model needs to be agreed by the CLT to determine exactly which activities will be performed by the A&DM and IT SD teams 10-Jan: updated with new column data; added a required risk res date (prev blank) of 31-Jan. 02/11 - Candidate applications for Phase 1 being received from the Assurance organisation; currently being reviewed against entry criteria 18/05 - Deferred. Lower priority. 11/05 - No applications identified yet, thus no users. Leave as is until identify the 15 apps (SOW was updated to specify the identification of 15 apps that already have requirements). 22/11 - Phase 1 project team are defining a 'calendar of events' to be sent to the business which will outline the support required over the coming months (incl. UAT) 14/12 - 1st draft 'calendar of events' sent to business reps for first few applications - awaiting confirmation to understand if they can meet the demands | X7: 40968 | Y7: Program Director | AA7: 40947 | AE7: =$AE$1-Table4[[#This Row],[Date Captured]] -> 316 | AF7: =IFERROR(OR(Table4[[#This Row],[Status]]="02. Open & Assigned",Table4[[#This Row],[Status]]="01. Open",Table4[[#This Row],[Status]]="03. Action/Mitigation Plan Defined",Table4[[#This Row],[Status]]="04. Action Plan Completed",Table4[[#This Row],[Status]]="08. Blank"),"") -> FALSE | AG7: =IF(Table4[[#This Row],[Required Risk Resolution Date]]="","FALSE",IF($AE$1>Table4[[#This Row],[Required Risk Resolution Date]],TRUE,FALSE)) -> TRUE | AH7: =IF(AE7<30,FALSE,IF(AE7>90,FALSE,TRUE)) -> FALSE | AI7: =IF(AE7<91,FALSE,IF(AE7>180,FALSE,TRUE)) -> FALSE | AJ7: =IF(AE7>180,TRUE,FALSE) -> TRUE | AK7: =OR(Table4[[#This Row],[Priority]]="Critical",Table4[[#This Row],[Priority]]="High") -> TRUE | AL7: =Table4[[#This Row],[Required Risk Resolution Date]]-$AE$1 -> -43 | AM7: =IF(AL7<1,FALSE,IF(AL7>7,FALSE,TRUE)) -> FALSE | AN7: =OR(Table4[[#This Row],[Priority]]="Critical",Table4[[#This Row],[Priority]]="High",Table4[[#This Row],[Priority]]="Moderate") -> TRUE
A8: R27 | B8: 40674 | C8: unknown | D8: 05. Risk Closed | E8: Msft delivery approach unclear to EY. In addition, SOW has insufficient detail. | F8: Microsoft development effort estimating method unclear, and estimates appear to be nominal. | G8: The timelines within the project plans for Phase 1 may be invalid. | H8: App and Data Migration | J8: Neil Sahdev | K8: Nicola Cooper | L8: Moderate | M8: 01. Impact < 4 weeks | N8: 04. Probable | O8: 02. Medium | P8: 02. Medium | Q8: 02. Medium | R8: 02. Medium | S8: When Msft starts delivering, if they are unable to meet required timelines and quality standards, this will occur. | T8: Mitigation | U8: None - To avoid numerous issues during delivery it is critical that we have a clear and unambiguous SoW between MS and EY | V8: Update the SOW to clarify the points needing clarification | W8: 14-Feb: Decision made to stand-down MSFT development team until key inbound dependancy dates are known (i.e. design of sharepoint components). Risk can be closed. 07-Feb: EY Phase 1 PM has documented all areas that need updating in the SoW (namely testing approach, environment provisioning, timelines, location of resources and roles and responsibililities) 18-Jan: Agreement reached with MS to document areas in the contract that need clarifying which will be discussed later in Jan'12 10-Jan: updated, filling in new columns. Added a req res date of 31-Jan. 30/08 - Engaged with MS to better understand their approach/timelines, etc. 18/05 - Deferred. Lower priority. 11/05 - Will clear this up one MS gets in and can answer our questions. 22/05 - Following a series of calls the MS delivery method for App Transformation and Data Migration is now known and understood. | X8: 40954 | Y8: Program Director | Z8: MSFT team stood down | AA8: 40941 | AB8: 40954 | AE8: =$AE$1-Table4[[#This Row],[Date Captured]] -> 316 | AF8: =IFERROR(OR(Table4[[#This Row],[Status]]="02. Open & Assigned",Table4[[#This Row],[Status]]="01. Open",Table4[[#This Row],[Status]]="03. Action/Mitigation Plan Defined",Table4[[#This Row],[Status]]="04. Action Plan Completed",Table4[[#This Row],[Status]]="08. Blank"),"") -> FALSE | AG8: =IF(Table4[[#This Row],[Required Risk Resolution Date]]="","FALSE",IF($AE$1>Table4[[#This Row],[Required Risk Resolution Date]],TRUE,FALSE)) -> TRUE | AH8: =IF(AE8<30,FALSE,IF(AE8>90,FALSE,TRUE)) -> FALSE | AI8: =IF(AE8<91,FALSE,IF(AE8>180,FALSE,TRUE)) -> FALSE | AJ8: =IF(AE8>180,TRUE,FALSE) -> TRUE | AK8: =OR(Table4[[#This Row],[Priority]]="Critical",Table4[[#This Row],[Priority]]="High") -> FALSE | AL8: =Table4[[#This Row],[Required Risk Resolution Date]]-$AE$1 -> -49 | AM8: =IF(AL8<1,FALSE,IF(AL8>7,FALSE,TRUE)) -> FALSE | AN8: =OR(Table4[[#This Row],[Priority]]="Critical",Table4[[#This Row],[Priority]]="High",Table4[[#This Row],[Priority]]="Moderate") -> TRUE
A9: R50A | B9: 40731 | D9: 05. Risk Closed | F9: Impact of 'Discovery & Assessment' program unknown. If treated as a prerequisite, will impact schedule significantly. | H9: App and Data Migration | J9: Neil Sahdev | N9: 04. Probable | O9: 03. High | W9: 05/10 - Close. 07/09 - Neil: have Discovery and Assessment team identifying apps among Lotus and Lotus Notes. Working to make sure we don't duplicate effort. Neil has long list of actions taking in next couple weeks to mitigate. Follow-up in 2 weeks. | X9: 40821 | Z9: Align approaches between A&DM and D&A Programs. | AB9: 40821 | AE9: =$AE$1-Table4[[#This Row],[Date Captured]] -> 259 | AF9: =IFERROR(OR(Table4[[#This Row],[Status]]="02. Open & Assigned",Table4[[#This Row],[Status]]="01. Open",Table4[[#This Row],[Status]]="03. Action/Mitigation Plan Defined",Table4[[#This Row],[Status]]="04. Action Plan Completed",Table4[[#This Row],[Status]]="08. Blank"),"") -> FALSE | AG9: =IF(Table4[[#This Row],[Required Risk Resolution Date]]="","FALSE",IF($AE$1>Table4[[#This Row],[Required Risk Resolution Date]],TRUE,FALSE)) -> FALSE | AH9: =IF(AE9<30,FALSE,IF(AE9>90,FALSE,TRUE)) -> FALSE | AI9: =IF(AE9<91,FALSE,IF(AE9>180,FALSE,TRUE)) -> FALSE | AJ9: =IF(AE9>180,TRUE,FALSE) -> TRUE | AK9: =OR(Table4[[#This Row],[Priority]]="Critical",Table4[[#This Row],[Priority]]="High") -> FALSE | AL9: =Table4[[#This Row],[Required Risk Resolution Date]]-$AE$1 -> -40990 | AM9: =IF(AL9<1,FALSE,IF(AL9>7,FALSE,TRUE)) -> FALSE | AN9: =OR(Table4[[#This Row],[Priority]]="Critical",Table4[[#This Row],[Priority]]="High",Table4[[#This Row],[Priority]]="Moderate") -> FALSE
A10: R51A | B10: 40731 | D10: 05. Risk Closed | F10: Impact of Data Centre Consolidation Program and associated "Application Remediation" activity is unknown. | H10: App and Data Migration | J10: Neil Sahdev | N10: 04. Probable | O10: 03. High | W10: 05/10 - Close. | X10: 40821 | Z10: Align approaches between A&DM and DCC Programs. | AB10: 40821 | AE10: =$AE$1-Table4[[#This Row],[Date Captured]] -> 259 | AF10: =IFERROR(OR(Table4[[#This Row],[Status]]="02. Open & Assigned",Table4[[#This Row],[Status]]="01. Open",Table4[[#This Row],[Status]]="03. Action/Mitigation Plan Defined",Table4[[#This Row],[Status]]="04. Action Plan Completed",Table4[[#This Row],[Status]]="08. Blank"),"") -> FALSE | AG10: =IF(Table4[[#This Row],[Required Risk Resolution Date]]="","FALSE",IF($AE$1>Table4[[#This Row],[Required Risk Resolution Date]],TRUE,FALSE)) -> FALSE | AH10: =IF(AE10<30,FALSE,IF(AE10>90,FALSE,TRUE)) -> FALSE | AI10: =IF(AE10<91,FALSE,IF(AE10>180,FALSE,TRUE)) -> FALSE | AJ10: =IF(AE10>180,TRUE,FALSE) -> TRUE | AK10: =OR(Table4[[#This Row],[Priority]]="Critical",Table4[[#This Row],[Priority]]="High") -> FALSE | AL10: =Table4[[#This Row],[Required Risk Resolution Date]]-$AE$1 -> -40990 | AM10: =IF(AL10<1,FALSE,IF(AL10>7,FALSE,TRUE)) -> FALSE | AN10: =OR(Table4[[#This Row],[Priority]]="Critical",Table4[[#This Row],[Priority]]="High",Table4[[#This Row],[Priority]]="Moderate") -> FALSE
A11: R52A | B11: 40731 | C11: unknown | D11: 05. Risk Closed | F11: Program is continuing without stakeholder engagement and consequently no agreed charter. | H11: App and Data Migration | J11: Neil Sahdev | L11: Moderate | N11: 03. Possible | O11: 02. Medium | W11: 10-Jan: This is included in R26. Updated wording in R26 to be clearly inclusive and closed this item (Neil and Laura). 02/11 - Program has varying level of engagement from >80% of Service Lines / CBS functions - plans in place to fully engage with remaining areas 05/10 - Monitor this item; push out date one month to November. 22/11 - Engagement with Service Lines / CBS functions continues to mature; team are now working on specific comms to be published to the teams outlining the support required from them over the coming months | X11: 40919 | Z11: Included in R26 (10-Jan) | AB11: 40918 | AC11: R26 | AE11: =$AE$1-Table4[[#This Row],[Date Captured]] -> 259 | AF11: =IFERROR(OR(Table4[[#This Row],[Status]]="02. Open & Assigned",Table4[[#This Row],[Status]]="01. Open",Table4[[#This Row],[Status]]="03. Action/Mitigation Plan Defined",Table4[[#This Row],[Status]]="04. Action Plan Completed",Table4[[#This Row],[Status]]="08. Blank"),"") -> FALSE | AG11: =IF(Table4[[#This Row],[Required Risk Resolution Date]]="","FALSE",IF($AE$1>Table4[[#This Row],[Required Risk Resolution Date]],TRUE,FALSE)) -> FALSE | AH11: =IF(AE11<30,FALSE,IF(AE11>90,FALSE,TRUE)) -> FALSE | AI11: =IF(AE11<91,FALSE,IF(AE11>180,FALSE,TRUE)) -> FALSE | AJ11: =IF(AE11>180,TRUE,FALSE) -> TRUE | AK11: =OR(Table4[[#This Row],[Priority]]="Critical",Table4[[#This Row],[Priority]]="High") -> FALSE | AL11: =Table4[[#This Row],[Required Risk Resolution Date]]-$AE$1 -> -40990 | AM11: =IF(AL11<1,FALSE,IF(AL11>7,FALSE,TRUE)) -> FALSE | AN11: =OR(Table4[[#This Row],[Priority]]="Critical",Table4[[#This Row],[Priority]]="High",Table4[[#This Row],[Priority]]="Moderate") -> TRUE
A12: R53 | B12: 40731 | D12: 05. Risk Closed | F12: Program is being treated as a technical migration program, with no reference back to business process and/or EY's strategic objectives. | H12: App and Data Migration | J12: Neil Sahdev | N12: 04. Probable | O12: 03. High | W12: 05/10 - Neil confirmed this has been resolved. Close. | X12: 40821 | Z12: Build approach to include business interlock, the BCFs and Solution Roadmaps. | AB12: 40821 | AE12: =$AE$1-Table4[[#This Row],[Date Captured]] -> 259 | AF12: =IFERROR(OR(Table4[[#This Row],[Status]]="02. Open & Assigned",Table4[[#This Row],[Status]]="01. Open",Table4[[#This Row],[Status]]="03. Action/Mitigation Plan Defined",Table4[[#This Row],[Status]]="04. Action Plan Completed",Table4[[#This Row],[Status]]="08. Blank"),"") -> FALSE | AG12: =IF(Table4[[#This Row],[Required Risk Resolution Date]]="","FALSE",IF($AE$1>Table4[[#This Row],[Required Risk Resolution Date]],TRUE,FALSE)) -> FALSE | AH12: =IF(AE12<30,FALSE,IF(AE12>90,FALSE,TRUE)) -> FALSE | AI12: =IF(AE12<91,FALSE,IF(AE12>180,FALSE,TRUE)) -> FALSE | AJ12: =IF(AE12>180,TRUE,FALSE) -> TRUE | AK12: =OR(Table4[[#This Row],[Priority]]="Critical",Table4[[#This Row],[Priority]]="High") -> FALSE | AL12: =Table4[[#This Row],[Required Risk Resolution Date]]-$AE$1 -> -40990 | AM12: =IF(AL12<1,FALSE,IF(AL12>7,FALSE,TRUE)) -> FALSE | AN12: =OR(Table4[[#This Row],[Priority]]="Critical",Table4[[#This Row],[Priority]]="High",Table4[[#This Row],[Priority]]="Moderate") -> FALSE
A13: R54 | B13: 40785 | D13: 05. Risk Closed | F13: Most applications do not have existing documentation (technical, business, testing, etc.) so A&DM program will need to factor into future plans. | H13: App and Data Migration | J13: Neil Sahdev | N13: 04. Probable | O13: 02. Medium | W13: 12/10 - Risk closed, documentation is know to be poor or non-existent. Planning assumption. | X13: 40821 | Z13: Make allowances in the detailed plans progressing through Sept '11. | AB13: 40828 | AE13: =$AE$1-Table4[[#This Row],[Date Captured]] -> 205 | AF13: =IFERROR(OR(Table4[[#This Row],[Status]]="02. Open & Assigned",Table4[[#This Row],[Status]]="01. Open",Table4[[#This Row],[Status]]="03. Action/Mitigation Plan Defined",Table4[[#This Row],[Status]]="04. Action Plan Completed",Table4[[#This Row],[Status]]="08. Blank"),"") -> FALSE | AG13: =IF(Table4[[#This Row],[Required Risk Resolution Date]]="","FALSE",IF($AE$1>Table4[[#This Row],[Required Risk Resolution Date]],TRUE,FALSE)) -> FALSE | AH13: =IF(AE13<30,FALSE,IF(AE13>90,FALSE,TRUE)) -> FALSE | AI13: =IF(AE13<91,FALSE,IF(AE13>180,FALSE,TRUE)) -> FALSE | AJ13: =IF(AE13>180,TRUE,FALSE) -> TRUE | AK13: =OR(Table4[[#This Row],[Priority]]="Critical",Table4[[#This Row],[Priority]]="High") -> FALSE | AL13: =Table4[[#This Row],[Required Risk Resolution Date]]-$AE$1 -> -40990 | AM13: =IF(AL13<1,FALSE,IF(AL13>7,FALSE,TRUE)) -> FALSE | AN13: =OR(Table4[[#This Row],[Priority]]="Critical",Table4[[#This Row],[Priority]]="High",Table4[[#This Row],[Priority]]="Moderate") -> FALSE
A14: R55 | B14: 40785 | D14: 05. Risk Closed | F14: Most applications have not undergone a security review so this will need to be factored in future plans (est. 10->20 days / application) | H14: App and Data Migration | J14: Neil Sahdev | N14: 04. Probable | O14: 02. Medium | W14: 12/10 - Risk closed, captured as an activity. | X14: 40821 | Z14: Make allowances in the detailed plans progressing through Sept '11. | AB14: 40828 | AE14: =$AE$1-Table4[[#This Row],[Date Captured]] -> 205 | AF14: =IFERROR(OR(Table4[[#This Row],[Status]]="02. Open & Assigned",Table4[[#This Row],[Status]]="01. Open",Table4[[#This Row],[Status]]="03. Action/Mitigation Plan Defined",Table4[[#This Row],[Status]]="04. Action Plan Completed",Table4[[#This Row],[Status]]="08. Blank"),"") -> FALSE | AG14: =IF(Table4[[#This Row],[Required Risk Resolution Date]]="","FALSE",IF($AE$1>Table4[[#This Row],[Required Risk Resolution Date]],TRUE,FALSE)) -> FALSE | AH14: =IF(AE14<30,FALSE,IF(AE14>90,FALSE,TRUE)) -> FALSE | AI14: =IF(AE14<91,FALSE,IF(AE14>180,FALSE,TRUE)) -> FALSE | AJ14: =IF(AE14>180,TRUE,FALSE) -> TRUE | AK14: =OR(Table4[[#This Row],[Priority]]="Critical",Table4[[#This Row],[Priority]]="High") -> FALSE | AL14: =Table4[[#This Row],[Required Risk Resolution Date]]-$AE$1 -> -40990 | AM14: =IF(AL14<1,FALSE,IF(AL14>7,FALSE,TRUE)) -> FALSE | AN14: =OR(Table4[[#This Row],[Priority]]="Critical",Table4[[#This Row],[Priority]]="High",Table4[[#This Row],[Priority]]="Moderate") -> FALSE
A15: R66 | B15: 40842 | D15: 07. Risk has become an Issue | F15: Lack of space in the Becket House, London office is preventing team from working in a co-located environment. | G15: 40844 | H15: App and Data Migration | J15: TBC | N15: 03. Possible | O15: 02. Medium | T15: Mitigation | V15: Seek necessary approvals to procure space for the team | W15: 22/11/11 - Escalated to an Issue (# I64) | X15: 40842 | AB15: 40869 | AC15: I64 | AE15: =$AE$1-Table4[[#This Row],[Date Captured]] -> 148 | AF15: =IFERROR(OR(Table4[[#This Row],[Status]]="02. Open & Assigned",Table4[[#This Row],[Status]]="01. Open",Table4[[#This Row],[Status]]="03. Action/Mitigation Plan Defined",Table4[[#This Row],[Status]]="04. Action Plan Completed",Table4[[#This Row],[Status]]="08. Blank"),"") -> FALSE | AG15: =IF(Table4[[#This Row],[Required Risk Resolution Date]]="","FALSE",IF($AE$1>Table4[[#This Row],[Required Risk Resolution Date]],TRUE,FALSE)) -> FALSE | AH15: =IF(AE15<30,FALSE,IF(AE15>90,FALSE,TRUE)) -> FALSE | AI15: =IF(AE15<91,FALSE,IF(AE15>180,FALSE,TRUE)) -> TRUE | AJ15: =IF(AE15>180,TRUE,FALSE) -> FALSE | AK15: =OR(Table4[[#This Row],[Priority]]="Critical",Table4[[#This Row],[Priority]]="High") -> FALSE | AL15: =Table4[[#This Row],[Required Risk Resolution Date]]-$AE$1 -> -40990 | AM15: =IF(AL15<1,FALSE,IF(AL15>7,FALSE,TRUE)) -> FALSE | AN15: =OR(Table4[[#This Row],[Priority]]="Critical",Table4[[#This Row],[Priority]]="High",Table4[[#This Row],[Priority]]="Moderate") -> FALSE
A16: R67 | B16: 40842 | C16: unknown | D16: 05. Risk Closed | E16: Significant number of resources required to deliver program. | F16: Approval is required to onboard required resources (as per the resource forecast) to prevent delays to delivery. In addition agreement is needed on the resourcing strategy (i.e. blend of ITS, contractors and CBS / Markets resources) | G16: Delays in gaining approval to onboard project resources will impact project timelines. | H16: App and Data Migration | J16: Neil Sahdev / Martin Stutchbury | K16: Neil Sahdev | L16: Critical | M16: 01. Impact < 4 weeks | N16: 04. Probable | O16: 01. Low | P16: 01. Low | Q16: 04. Critical | R16: 02. Medium | S16: Not getting necessary approvals in time to procure resources. | T16: Mitigation | U16: None - Agreement needs to be reached between the IT SD teams and Cross-Org on where the resources required for the A&DM Program will be sourced from | V16: 1) Ensure all resource requests are in the Resource Request DB and align to project plans - complete 2) Meeting to be scheduled with Margaret Walsh and Christopher Hall to determine percentage of permanent employees to recruit and utilise in the Program - in progress; meetings held, agreement yet to be reached. 3) Agree resourcing strategy / mix with Markets and CBS - in progress (meetings set-up with People and Assurance IT Service Delivery Leaders) 4) Agree Operating Model between x-org and IT SD teams - in progress (proposed A&DM operating model sent to Chris, Margaret and Alan for review / discussion at next CLT meeting scheduled 24/01/12) | W16: 06-Mar: Risk closed as decision (D75B) raised to track agreement to both the A&DM Operating Model and Resourcing Strategy 22-Feb: inc. in man. pack; still waiting to hear on Operating Model. 15-Feb: Neil reqd we include in man. pack again; need decision. 08-Feb: This corresponds with above (R26); need agreement on operating model. Neil would like this raised in mng. pack as well. 07-Feb: Awaiting decision 25-Jan: Awaiting decision from CLT ref preferred resourcing strategy for the Program. Neil sent Mike Laci latest deck (Mike involved on Operating Model team). Neil requested this go to the weekly Management Pack for Guy/Alan. 18-Jan: Portfolio 1 and 2 start dates 1-July; plan has been updated accordingly. Alan working with Mo to determine where the resolution will come from. Review next week. 10-Jan: updated all columns, added risk res date of 31-Jan. | X16: 40968 | Y16: Managing Sponsor | AA16: 40954 | AE16: =$AE$1-Table4[[#This Row],[Date Captured]] -> 148 | AF16: =IFERROR(OR(Table4[[#This Row],[Status]]="02. Open & Assigned",Table4[[#This Row],[Status]]="01. Open",Table4[[#This Row],[Status]]="03. Action/Mitigation Plan Defined",Table4[[#This Row],[Status]]="04. Action Plan Completed",Table4[[#This Row],[Status]]="08. Blank"),"") -> FALSE | AG16: =IF(Table4[[#This Row],[Required Risk Resolution Date]]="","FALSE",IF($AE$1>Table4[[#This Row],[Required Risk Resolution Date]],TRUE,FALSE)) -> TRUE | AH16: =IF(AE16<30,FALSE,IF(AE16>90,FALSE,TRUE)) -> FALSE | AI16: =IF(AE16<91,FALSE,IF(AE16>180,FALSE,TRUE)) -> TRUE | AJ16: =IF(AE16>180,TRUE,FALSE) -> FALSE | AK16: =OR(Table4[[#This Row],[Priority]]="Critical",Table4[[#This Row],[Priority]]="High") -> TRUE | AL16: =Table4[[#This Row],[Required Risk Resolution Date]]-$AE$1 -> -36 | AM16: =IF(AL16<1,FALSE,IF(AL16>7,FALSE,TRUE)) -> FALSE | AN16: =OR(Table4[[#This Row],[Priority]]="Critical",Table4[[#This Row],[Priority]]="High",Table4[[#This Row],[Priority]]="Moderate") -> TRUE
A17: R74 | B17: 40848 | C17: unknown | D17: 05. Risk Closed | F17: To maintain the Program schedule it is important that the Business and IT Service Delivery teams nominate empowered decision makers for each Service Line / CBS function who can readily review / approve Program deliverables and work products. This includes having one decision maker in cases where there are multiple stakeholders (i.e. where an application is owned by one organisation yet consumed by multiple organisations). | H17: App and Data Migration | J17: Neil Sahdev | L17: High | N17: 03. Possible | O17: 03. High | T17: Mitigation | V17: 7/21/11 - Meetings held with Assurance, People, Knowledge, Markets, Comms & Marketing. Scheduled time with Margaret Walsh for 7/12/11 to outline resource requirement and sourcing strategy. Provide the business (Assurance initially for Phase 1) with a clear calendar of events outlining what support is needed (i.e. workshop participation, document reviews, decisions required....) from them over the coming months. | W17: 10-Jan: Closed this risk; this is included in R26. 14/12 - Meetings held with Margaret and Chris to agree A&DM Operating Model - agreement reached for Decomm, Archive and Data Migration; operating model for App Transformation to be finalised 07/12 - Meeting with Margaret today; review next week. 30/11 - Neil and Martin have conversation planned with Assurance for Monday. Thereafter Neil will update this item accordingly. 09/11 - date out end of month. 02/11 - Neil will pick up offline with Michelle for update here. | X17: 40898 | Z17: Included in R26 (10-Jan) | AB17: 40918 | AC17: R26 | AE17: =$AE$1-Table4[[#This Row],[Date Captured]] -> 142 | AF17: =IFERROR(OR(Table4[[#This Row],[Status]]="02. Open & Assigned",Table4[[#This Row],[Status]]="01. Open",Table4[[#This Row],[Status]]="03. Action/Mitigation Plan Defined",Table4[[#This Row],[Status]]="04. Action Plan Completed",Table4[[#This Row],[Status]]="08. Blank"),"") -> FALSE | AG17: =IF(Table4[[#This Row],[Required Risk Resolution Date]]="","FALSE",IF($AE$1>Table4[[#This Row],[Required Risk Resolution Date]],TRUE,FALSE)) -> FALSE | AH17: =IF(AE17<30,FALSE,IF(AE17>90,FALSE,TRUE)) -> FALSE | AI17: =IF(AE17<91,FALSE,IF(AE17>180,FALSE,TRUE)) -> TRUE | AJ17: =IF(AE17>180,TRUE,FALSE) -> FALSE | AK17: =OR(Table4[[#This Row],[Priority]]="Critical",Table4[[#This Row],[Priority]]="High") -> TRUE | AL17: =Table4[[#This Row],[Required Risk Resolution Date]]-$AE$1 -> -40990 | AM17: =IF(AL17<1,FALSE,IF(AL17>7,FALSE,TRUE)) -> FALSE | AN17: =OR(Table4[[#This Row],[Priority]]="Critical",Table4[[#This Row],[Priority]]="High",Table4[[#This Row],[Priority]]="Moderate") -> TRUE
A18: R78A | B18: 40869 | C18: unknown | D18: 05. Risk Closed | E18: Large number of applications needed to be assessed for Phase 1. | F18: To-date the Phase 1 BA team have had to analyse nearly 40 applications to identify 5 which can be progressed. Based on this the team would need to analyse another 80 applications to identify the remaining 10 applications required for Phase 1. | G18: Analysing such large quantities of applications was never planned for and as a result the Phase 1 project plan has been updated to reflect this for the remaining applications that need to be identified. If this ratio of 8 canditates : 1 identied application increases then the project plans will need to be further updated. | H18: App and Data Migration | J18: Neil Sahdev | K18: Nicola Cooper | L18: Moderate | M18: 01. Impact < 4 weeks | N18: 03. Possible | O18: 02. Medium | P18: 01. Low | Q18: 02. Medium | R18: 02. Medium | S18: If Phase 1 BA team is unable to identify and baseline 15 required applications for Phase 1, will occur. | T18: Mitigation | U18: None - Need to ensure sufficient analysis time is allowed for in the plans | V18: 1, Update Phase 1 project plans to take analysis effort into account - complete 2. Monitor the effort expended vs. Planned for the remaining 10 applications - in progress (team are heavily dependant on knowing exactly what the Sharepoint Program will deliver and when) | W18: 07/03 - Risk closed as replanning being managed as a BAU activity 29/02 - Replanning underway following decision to offboard 2 Phase 1 BA resources 22/02 - Since two members of the Phase 1 BA team are being offboarded due to budget reasons the delivery dates are being impacted. It is therefore likely that candidate applications will be descoped from Phase 1 as they can no longer be delivered within the timelines requested by the business. 14/02 - Same status as 07/02/12 07/02 - Phase 1 BA team are heavily dependant on knowing exactly what the Sharepoint Program will deliver and when to baseline the 15 applications 23/11 - Push out 1 month for next review. | X18: 40975 | Y18: Program Director | AA18: 40954 | AE18: =$AE$1-Table4[[#This Row],[Date Captured]] -> 121 | AF18: =IFERROR(OR(Table4[[#This Row],[Status]]="02. Open & Assigned",Table4[[#This Row],[Status]]="01. Open",Table4[[#This Row],[Status]]="03. Action/Mitigation Plan Defined",Table4[[#This Row],[Status]]="04. Action Plan Completed",Table4[[#This Row],[Status]]="08. Blank"),"") -> FALSE | AG18: =IF(Table4[[#This Row],[Required Risk Resolution Date]]="","FALSE",IF($AE$1>Table4[[#This Row],[Required Risk Resolution Date]],TRUE,FALSE)) -> TRUE | AH18: =IF(AE18<30,FALSE,IF(AE18>90,FALSE,TRUE)) -> FALSE | AI18: =IF(AE18<91,FALSE,IF(AE18>180,FALSE,TRUE)) -> TRUE | AJ18: =IF(AE18>180,TRUE,FALSE) -> FALSE | AK18: =OR(Table4[[#This Row],[Priority]]="Critical",Table4[[#This Row],[Priority]]="High") -> FALSE | AL18: =Table4[[#This Row],[Required Risk Resolution Date]]-$AE$1 -> -36 | AM18: =IF(AL18<1,FALSE,IF(AL18>7,FALSE,TRUE)) -> FALSE | AN18: =OR(Table4[[#This Row],[Priority]]="Critical",Table4[[#This Row],[Priority]]="High",Table4[[#This Row],[Priority]]="Moderate") -> TRUE
A19: R87 | B19: 40918 | C19: Neil Sahdev | D19: 07. Risk has become an Issue | E19: Currently discovery team largely staffed with IT advisory resources for a finite period of time. | F19: As the Rediscovery project is now expected to complete June 2012, there is a need to extend the resources of the team. If the resources can't be extended, we will lose them. | G19: We will have to identify and onboard new resources, therefore affecting the timelines. | H19: App and Data Migration | J19: Neil Sahdev | K19: Akos Rabi | L19: High | M19: 01. Impact < 4 weeks | N19: 05. Certain | O19: 01. Low | P19: 01. Low | Q19: 03. High | R19: 03. High | S19: Team can't be extended. | T19: Mitigation | V19: Extend resources | W19: 25-Jan: 3 x ITA resources expected to leave end-Jan'12/early-Feb'12. 2 x resources (1 PM and 1 data analyst) required to backfill however no suitable candidates identified so far. 18-Jan: Approval received from Alan to extend team; Martin now engaging with ITA to agree revised end-dates for each of the resources (which is dependant on start date of their next engagement) 11-Jan: Neil is meeting with Lindsey tomorrow on this topic; should have more information for next week's call. 10-Jan - opened by Neil. | X19: 40933 | Y19: Program Director | Z19: This is no longer a risk, but an issue. 25-Jan made issue #I104. | AA19: 40939 | AB19: 40933 | AC19: I104 | AE19: =$AE$1-Table4[[#This Row],[Date Captured]] -> 72 | AF19: =IFERROR(OR(Table4[[#This Row],[Status]]="02. Open & Assigned",Table4[[#This Row],[Status]]="01. Open",Table4[[#This Row],[Status]]="03. Action/Mitigation Plan Defined",Table4[[#This Row],[Status]]="04. Action Plan Completed",Table4[[#This Row],[Status]]="08. Blank"),"") -> FALSE | AG19: =IF(Table4[[#This Row],[Required Risk Resolution Date]]="","FALSE",IF($AE$1>Table4[[#This Row],[Required Risk Resolution Date]],TRUE,FALSE)) -> TRUE | AH19: =IF(AE19<30,FALSE,IF(AE19>90,FALSE,TRUE)) -> TRUE | AI19: =IF(AE19<91,FALSE,IF(AE19>180,FALSE,TRUE)) -> FALSE | AJ19: =IF(AE19>180,TRUE,FALSE) -> FALSE | AK19: =OR(Table4[[#This Row],[Priority]]="Critical",Table4[[#This Row],[Priority]]="High") -> TRUE | AL19: =Table4[[#This Row],[Required Risk Resolution Date]]-$AE$1 -> -51 | AM19: =IF(AL19<1,FALSE,IF(AL19>7,FALSE,TRUE)) -> FALSE | AN19: =OR(Table4[[#This Row],[Priority]]="Critical",Table4[[#This Row],[Priority]]="High",Table4[[#This Row],[Priority]]="Moderate") -> TRUE
A20: R88 | B20: 40918 | C20: Neil Sahdev | D20: 02. Open & Assigned | E20: The Rediscovery project team need access to Lotus applications to perform analysis | F20: The Rediscovery team does not have the required level of access and therefore can't perform analysis. | G20: Team cannot complete analysis. | H20: App and Data Migration | J20: Neil Sahdev | K20: Christian Driver | L20: Moderate | M20: 01. Impact < 4 weeks | N20: 05. Certain | O20: 01. Low | P20: 01. Low | Q20: 03. High | R20: 01. Low | S20: Team can't get necessary access | T20: Mitigation | U20: None - Team require access to perform analysis | V20: Gain necessary approval from Q&RM and security and operations to grant team required access | W20: 06-Mar: Recently onboarded Rediscovery PM now working with Operations and Q&RM to agree accesses required to these applications 22-Feb: Confirmation received from Q&RM ref gaining access to applications without sensitive data or not in the 'red box' countries; process to be defined for accessing these types of applications 15-Feb: Steve - Susan was documenting her statement around what will be in and out of scope for access. Neil will update further. 18-Jan: This was due to be addressed at the Q&RM Steering Group scheduled 26th Jan'12 however it has now been cancelled. Steve provided update that he spoke with Susan yesterday and this is being moved forward outside of the Steering Group. Should gain clarity by the end of the week. 11-Jan: Operations agreed which data they need in order to get the access. Review in two weeks (for probable ability to close). 10-Jan - opened by Neil. 30 Jan - QRM meeting to make decision cancelled, chasing up outside of normal channels but no decision made yet. | X20: 40991 | Y20: Program Director | AA20: 40998 | AE20: =$AE$1-Table4[[#This Row],[Date Captured]] -> 72 | AF20: =IFERROR(OR(Table4[[#This Row],[Status]]="02. Open & Assigned",Table4[[#This Row],[Status]]="01. Open",Table4[[#This Row],[Status]]="03. Action/Mitigation Plan Defined",Table4[[#This Row],[Status]]="04. Action Plan Completed",Table4[[#This Row],[Status]]="08. Blank"),"") -> TRUE | AG20: =IF(Table4[[#This Row],[Required Risk Resolution Date]]="","FALSE",IF($AE$1>Table4[[#This Row],[Required Risk Resolution Date]],TRUE,FALSE)) -> FALSE | AH20: =IF(AE20<30,FALSE,IF(AE20>90,FALSE,TRUE)) -> TRUE | AI20: =IF(AE20<91,FALSE,IF(AE20>180,FALSE,TRUE)) -> FALSE | AJ20: =IF(AE20>180,TRUE,FALSE) -> FALSE | AK20: =OR(Table4[[#This Row],[Priority]]="Critical",Table4[[#This Row],[Priority]]="High") -> FALSE | AL20: =Table4[[#This Row],[Required Risk Resolution Date]]-$AE$1 -> 8 | AM20: =IF(AL20<1,FALSE,IF(AL20>7,FALSE,TRUE)) -> FALSE | AN20: =OR(Table4[[#This Row],[Priority]]="Critical",Table4[[#This Row],[Priority]]="High",Table4[[#This Row],[Priority]]="Moderate") -> TRUE
A21: R99 | B21: 40940 | C21: Neil Sahdev | D21: 05. Risk Closed | E21: Testing environments may not be available on time | F21: Turn around time for environment provisioning is currently 90 days. To intiate the process requires significant detailed design about the application so that the appropriate environment can be provisioned. This information is not available until the SDD/SAD and TDD have been completed. The development timeframe is short for MSFT, so the codeset will be provided back to us with no environment to put it into. | G21: Testing cannot start of the MSFT deliverables | H21: App and Data Migration | J21: Martin Stutchbury | K21: Nicola Cooper | L21: Moderate | M21: 01. Impact < 4 weeks | N21: 04. Probable | O21: 01. Low | P21: 01. Low | Q21: 03. High | R21: 02. Medium | S21: Unclear process for initial environment provisioning | T21: Mitigation | U21: None - Without environements the delivery schedule will be impacted | V21: Escalate within the Soln architects for Phase 1, and prioritise effort to complete (as best as known) environment requirements | W21: 06/03 - Risk closed as replanning is being managed as a BAU activity 29/02 - Replanning underway since understanding many inbound depenencies will not be delivered many months later than planned 22/02: The dates which the environments are needed by may change depending on the current Phase 1 replan 07-Feb: Phase 1 solution and infrastructure architect teams are working with TF to better understand what information they need to provision environments | X21: 40975 | Y21: Program Director | AA21: 40956 | AE21: =$AE$1-Table4[[#This Row],[Date Captured]] -> 50 | AF21: =IFERROR(OR(Table4[[#This Row],[Status]]="02. Open & Assigned",Table4[[#This Row],[Status]]="01. Open",Table4[[#This Row],[Status]]="03. Action/Mitigation Plan Defined",Table4[[#This Row],[Status]]="04. Action Plan Completed",Table4[[#This Row],[Status]]="08. Blank"),"") -> FALSE | AG21: =IF(Table4[[#This Row],[Required Risk Resolution Date]]="","FALSE",IF($AE$1>Table4[[#This Row],[Required Risk Resolution Date]],TRUE,FALSE)) -> TRUE | AH21: =IF(AE21<30,FALSE,IF(AE21>90,FALSE,TRUE)) -> TRUE | AI21: =IF(AE21<91,FALSE,IF(AE21>180,FALSE,TRUE)) -> FALSE | AJ21: =IF(AE21>180,TRUE,FALSE) -> FALSE | AK21: =OR(Table4[[#This Row],[Priority]]="Critical",Table4[[#This Row],[Priority]]="High") -> FALSE | AL21: =Table4[[#This Row],[Required Risk Resolution Date]]-$AE$1 -> -34 | AM21: =IF(AL21<1,FALSE,IF(AL21>7,FALSE,TRUE)) -> FALSE | AN21: =OR(Table4[[#This Row],[Priority]]="Critical",Table4[[#This Row],[Priority]]="High",Table4[[#This Row],[Priority]]="Moderate") -> TRUE
